Workbook

Sheet Main Page

Sheet Summary
A1: Main Page | E1: Data Source: ACEMF
A6: Fund Barometer
A7: Categories Average (Weighted) Returns of Mutual Funds (%) | F7: As on 30 Apr 2026
A8: Categories | B8: No. Of Funds | C8: Category AUM | D8: 1 Month | E8: 3 Months | F8: 6 Months | G8: YTD | H8: 1 Year | I8: 2 Years | J8: 3 Years | K8: 4 Years | L8: 5 Years | M8: 7 Years | N8: 10 Years | O8: 15 Years | P8: Since Inception | Q8: Riskometer | R8: Ideal Investment Horizon
A9: DEBT FUNDS
A10: OVERNIGHT FUND | B10: =COUNTA('Overnight Fund'!$A$12:A48) -> 35 | C10: =SUM('Overnight Fund'!$D$12:D48) -> 72684.159 | D10: ='Overnight Fund'!I49 -> 5.018624 | E10: ='Overnight Fund'!J49 -> 4.9608537 | F10: ='Overnight Fund'!K49 -> 5.1175713 | G10: ='Overnight Fund'!L49 -> 5.0309286 | H10: ='Overnight Fund'!M49 -> 5.3245389 | I10: ='Overnight Fund'!N49 -> 5.9064812 | J10: ='Overnight Fund'!O49 -> 6.1674722 | K10: ='Overnight Fund'!P49 -> 6.0284285 | ... P10: ='Overnight Fund'!U49 -> 5.5358493 | Q10: Low Risk | R10: 1 - 91 days
A11: MONEY MARKET FUND | B11: =COUNTA('Money Market Fund'!$A$12:A36) -> 25 | C11: =SUM('Money Market Fund'!$D$12:D36) -> 308493.18 | D11: ='Money Market Fund'!I37 -> 7.3410383 | E11: ='Money Market Fund'!J37 -> 6.2039874 | F11: ='Money Market Fund'!K37 -> 5.6947229 | G11: ='Money Market Fund'!L37 -> 5.5733219 | H11: ='Money Market Fund'!M37 -> 6.2367853 | I11: ='Money Market Fund'!N37 -> 7.0529306 | J11: ='Money Market Fund'!O37 -> 7.1494399 | K11: ='Money Market Fund'!P37 -> 6.8261301 | ... P11: ='Money Market Fund'!U37 -> 6.8677068 | Q11: Low to Moderate Risk | R11: 3 months and above
A12: LIQUID FUND | B12: =COUNTA('Liquid Fund'!$A$12:A50) -> 38 | C12: =SUM('Liquid Fund'!$D$12:D50) -> 458154.96 | D12: ='Liquid Fund'!I51 -> 7.9599094 | E12: ='Liquid Fund'!J51 -> 6.8154609 | F12: ='Liquid Fund'!K51 -> 6.2662544 | G12: ='Liquid Fund'!L51 -> 6.4296043 | H12: ='Liquid Fund'!M51 -> 6.1864692 | I12: ='Liquid Fund'!N51 -> 6.7179117 | J12: ='Liquid Fund'!O51 -> 6.8792412 | K12: ='Liquid Fund'!P51 -> 6.6344019 | ... P12: ='Liquid Fund'!U51 -> 6.7419505 | Q12: Low to Moderate Risk | R12: 1 - 91 days
A13: ULTRA SHORT DURATION FUND | B13: =COUNTA('Ultra Short Duration Fund'!$A$12:A36) -> 25 | C13: =SUM('Ultra Short Duration Fund'!$D$12:D36) -> 113337 | D13: ='Ultra Short Duration Fund'!I37 -> 6.8498355 | E13: ='Ultra Short Duration Fund'!J37 -> 6.4333905 | F13: ='Ultra Short Duration Fund'!K37 -> 5.6790969 | G13: ='Ultra Short Duration Fund'!L37 -> 5.6679864 | H13: ='Ultra Short Duration Fund'!M37 -> 6.160709 | I13: ='Ultra Short Duration Fund'!N37 -> 6.8293665 | J13: ='Ultra Short Duration Fund'!O37 -> 6.9113077 | K13: ='Ultra Short Duration Fund'!P37 -> 6.5679239 | ... P13: ='Ultra Short Duration Fund'!U37 -> 6.7398272 | Q13: Low to Moderate Risk | R13: 3 months and above
A14: LOW DURATION FUND | B14: =COUNTA('Low Duration Fund'!$A$12:A34) -> 23 | C14: =SUM('Low Duration Fund'!$D$12:D34) -> 129126.12 | D14: ='Low Duration Fund'!I35 -> 6.2826502 | E14: ='Low Duration Fund'!J35 -> 5.6493069 | F14: ='Low Duration Fund'!K35 -> 5.0344819 | G14: ='Low Duration Fund'!L35 -> 4.8411689 | H14: ='Low Duration Fund'!M35 -> 5.9325712 | I14: ='Low Duration Fund'!N35 -> 6.8932018 | J14: ='Low Duration Fund'!O35 -> 6.9622771 | K14: ='Low Duration Fund'!P35 -> 6.5944796 | ... P14: ='Low Duration Fund'!U35 -> 7.1690639 | Q14: Moderate Risk | R14: 6 months and above
A15: SHORT DURATION FUND | B15: =COUNTA('Short Duration Fund'!$A$12:A36) -> 24 | C15: =SUM('Short Duration Fund'!$D$12:D36) -> 110552.79 | D15: ='Short Duration Fund'!F37 -> 6.1822316 | E15: ='Short Duration Fund'!G37 -> 3.9319393 | F15: ='Short Duration Fund'!H37 -> 3.5250385 | G15: ='Short Duration Fund'!I37 -> 3.0670165 | H15: ='Short Duration Fund'!J37 -> 4.9511693 | I15: ='Short Duration Fund'!K37 -> 7.086151 | J15: ='Short Duration Fund'!L37 -> 6.931984 | K15: ='Short Duration Fund'!M37 -> 6.5584103 | ... P15: ='Short Duration Fund'!R37 -> 7.3413065 | Q15: Low to Moderate Risk | R15: 1 year and above
A16: MEDIUM DURATION FUND | B16: =COUNTA('Medium Duration Fund'!$A$12:A26) -> 13 | C16: =SUM('Medium Duration Fund'!$D$12:D26) -> 25528.301 | D16: ='Medium Duration Fund'!F27 -> 8.5009605 | E16: ='Medium Duration Fund'!G27 -> 4.0224072 | F16: ='Medium Duration Fund'!H27 -> 4.5107225 | G16: ='Medium Duration Fund'!I27 -> 3.974827 | H16: ='Medium Duration Fund'!J27 -> 5.4872556 | I16: ='Medium Duration Fund'!K27 -> 7.8764285 | J16: ='Medium Duration Fund'!L27 -> 7.4098555 | K16: ='Medium Duration Fund'!M27 -> 7.458557 | ... P16: ='Medium Duration Fund'!R27 -> 7.6597404 | Q16: Moderate Risk | R16: 2.5 years and above
A17: MEDIUM TO LONG DURATION FUND | B17: =COUNTA('Medium to Long Duration Fund'!$A$12:A24) -> 13 | C17: =SUM('Medium to Long Duration Fund'!$D$12:D24) -> 10769.245 | D17: ='Medium to Long Duration Fund'!F25 -> 10.498611 | E17: ='Medium to Long Duration Fund'!G25 -> 0.91890742 | F17: ='Medium to Long Duration Fund'!H25 -> 1.4010366 | G17: ='Medium to Long Duration Fund'!I25 -> 0.48000972 | H17: ='Medium to Long Duration Fund'!J25 -> 1.5405364 | I17: ='Medium to Long Duration Fund'!K25 -> 6.0061813 | J17: ='Medium to Long Duration Fund'!L25 -> 6.0290164 | K17: ='Medium to Long Duration Fund'!M25 -> 6.0377419 | ... P17: ='Medium to Long Duration Fund'!R25 -> 7.9637896 | Q17: Moderate Risk | R17: 2.5 years and above
A18: LONG DURATION FUND | B18: =COUNTA('Long Duration Fund'!$A$12:A22) -> 11 | C18: =SUM('Long Duration Fund'!$D$12:D22) -> 14158.737 | D18: ='Long Duration Fund'!F23 -> 19.964692 | E18: ='Long Duration Fund'!G23 -> -3.8485619 | F18: ='Long Duration Fund'!H23 -> -1.7235176 | G18: ='Long Duration Fund'!I23 -> -3.7805508 | H18: ='Long Duration Fund'!J23 -> -2.4856437 | I18: ='Long Duration Fund'!K23 -> 5.0270957 | J18: ='Long Duration Fund'!L23 -> 5.4909075 | K18: ='Long Duration Fund'!M23 -> 6.1419103 | ... P18: ='Long Duration Fund'!R23 -> 6.9479264 | Q18: Moderate Risk | R18: 5 years and above
A19: DYNAMIC BOND | B19: =COUNTA('Dynamic Bond'!$A$12:A34) -> 22 | C19: =SUM('Dynamic Bond'!$D$12:D34) -> 32385.878 | D19: ='Dynamic Bond'!F35 -> 10.145502 | E19: ='Dynamic Bond'!G35 -> 2.6479533 | F19: ='Dynamic Bond'!H35 -> 2.7748929 | G19: ='Dynamic Bond'!I35 -> 2.3191601 | H19: ='Dynamic Bond'!J35 -> 2.7805517 | I19: ='Dynamic Bond'!K35 -> 6.7680068 | J19: ='Dynamic Bond'!L35 -> 6.6749393 | K19: ='Dynamic Bond'!M35 -> 6.6131558 | ... P19: ='Dynamic Bond'!R35 -> 7.6110802 | Q19: Moderate Risk | R19: 2.5 years and above
A20: CORPORATE BOND FUND | B20: =COUNTA('Corporate Bond Fund'!$A$12:A32) -> 21 | C20: =SUM('Corporate Bond Fund'!$D$12:D32) -> 178530.72 | D20: ='Corporate Bond Fund'!F33 -> 6.6762327 | E20: ='Corporate Bond Fund'!G33 -> 3.2485229 | F20: ='Corporate Bond Fund'!H33 -> 2.8656602 | G20: ='Corporate Bond Fund'!I33 -> 2.1860598 | H20: ='Corporate Bond Fund'!J33 -> 4.4176321 | I20: ='Corporate Bond Fund'!K33 -> 7.0266031 | J20: ='Corporate Bond Fund'!L33 -> 6.9654242 | K20: ='Corporate Bond Fund'!M33 -> 6.5835124 | ... P20: ='Corporate Bond Fund'!R33 -> 7.4193768 | Q20: Low to Moderate Risk | R20: 1 year and above
A21: CREDIT RISK FUND | B21: =COUNTA('Credit Risk Fund'!$A$12:A25) -> 14 | C21: =SUM('Credit Risk Fund'!$D$12:D25) -> 19611.245 | D21: ='Credit Risk Fund'!F26 -> 10.133821 | E21: ='Credit Risk Fund'!G26 -> 6.2123875 | F21: ='Credit Risk Fund'!H26 -> 6.0516744 | G21: ='Credit Risk Fund'!I26 -> 6.0437784 | H21: ='Credit Risk Fund'!J26 -> 7.0956037 | I21: ='Credit Risk Fund'!K26 -> 8.5523855 | J21: ='Credit Risk Fund'!L26 -> 8.0274158 | K21: ='Credit Risk Fund'!M26 -> 7.4859902 | ... P21: ='Credit Risk Fund'!R26 -> 7.7701852 | Q21: Moderately High Risk | R21: 1 year and above
A22: BANKING AND PSU FUND | B22: =COUNTA('Banking and PSU Fund'!$A$12:A33) -> 21 | C22: =SUM('Banking and PSU Fund'!$D$12:D33) -> 74620.536 | D22: ='Banking and PSU Fund'!F34 -> 6.0849562 | E22: ='Banking and PSU Fund'!G34 -> 3.5933696 | F22: ='Banking and PSU Fund'!H34 -> 3.0352178 | G22: ='Banking and PSU Fund'!I34 -> 2.513271 | H22: ='Banking and PSU Fund'!J34 -> 4.4528002 | I22: ='Banking and PSU Fund'!K34 -> 6.8126548 | J22: ='Banking and PSU Fund'!L34 -> 6.6931729 | K22: ='Banking and PSU Fund'!M34 -> 6.3625287 | ... P22: ='Banking and PSU Fund'!R34 -> 7.3254755 | Q22: Moderate Risk | R22: 2.5 years and above
A23: GILT FUND | B23: =COUNTA('Gilt Fund'!$A$12:A34) -> 23 | C23: =SUM('Gilt Fund'!$D$12:D34) -> 33620.329 | D23: ='Gilt Fund'!F35 -> 14.78146 | E23: ='Gilt Fund'!G35 -> -0.11857476 | F23: ='Gilt Fund'!H35 -> 0.98249071 | G23: ='Gilt Fund'!I35 -> 0.10199944 | H23: ='Gilt Fund'!J35 -> -0.0099855513 | I23: ='Gilt Fund'!K35 -> 5.6803783 | J23: ='Gilt Fund'!L35 -> 5.9714539 | K23: ='Gilt Fund'!M35 -> 6.1390739 | ... P23: ='Gilt Fund'!R35 -> 8.1304676 | Q23: Low to Moderate Risk | R23: 2.5 years and above
A24: GILT FUND WITH 10 YR CONSTANT | B24: =COUNTA('Gilt Fund with 10 yr constant'!$A$12:A16) -> 5 | C24: =SUM('Gilt Fund with 10 yr constant'!D12:D16) -> 4520.8901 | D24: ='Gilt Fund with 10 yr constant'!F17 -> 8.5289767 | E24: ='Gilt Fund with 10 yr constant'!G17 -> -0.93472053 | F24: ='Gilt Fund with 10 yr constant'!H17 -> 1.238809 | G24: ='Gilt Fund with 10 yr constant'!I17 -> -0.68249692 | H24: ='Gilt Fund with 10 yr constant'!J17 -> 1.6709096 | I24: ='Gilt Fund with 10 yr constant'!K17 -> 6.9372475 | J24: ='Gilt Fund with 10 yr constant'!L17 -> 6.660324 | K24: ='Gilt Fund with 10 yr constant'!M17 -> 6.7053704 | ... P24: ='Gilt Fund with 10 yr constant'!R17 -> 7.8424381 | Q24: Low to Moderate Risk | R24: 5 years and above
A25: TARGET MATURITY FUND | B25: =COUNTA('Target Maturity Fund'!$A$12:A121) -> 110 | C25: =SUM('Target Maturity Fund'!$D$12:D121) -> 106289.12 | D25: ='Target Maturity Fund'!F122 -> 6.6095209 | E25: ='Target Maturity Fund'!G122 -> 4.8366798 | F25: ='Target Maturity Fund'!H122 -> 4.7994433 | G25: ='Target Maturity Fund'!I122 -> 4.5572008 | H25: ='Target Maturity Fund'!J122 -> 5.4502887 | I25: ='Target Maturity Fund'!K122 -> 7.3818032 | J25: ='Target Maturity Fund'!L122 -> 7.0781904 | K25: ='Target Maturity Fund'!M122 -> 6.6980808 | ... P25: ='Target Maturity Fund'!R122 -> 6.4879947 | Q25: Moderate Risk | R25: As per maturity date of bonds held
A26: FLOATER FUND | B26: =COUNTA('Floater Fund'!$A$12:A23) -> 12 | C26: =SUM('Floater Fund'!$D$12:D23) -> 51282.888 | D26: ='Floater Fund'!F24 -> 6.0248833 | E26: ='Floater Fund'!G24 -> 5.3090118 | F26: ='Floater Fund'!H24 -> 4.813167 | G26: ='Floater Fund'!I24 -> 4.443736 | H26: ='Floater Fund'!J24 -> 5.9245256 | I26: ='Floater Fund'!K24 -> 7.296562 | J26: ='Floater Fund'!L24 -> 7.4170374 | K26: ='Floater Fund'!M24 -> 6.9993243 | ... P26: ='Floater Fund'!R24 -> 7.5375418 | Q26: Moderate Risk | R26: 1 year and above
A27: HYBRID FUNDS
A28: ARBITRAGE FUND | B28: =COUNTA('Arbitrage Fund'!$A$12:A46) -> 35 | C28: =SUM('Arbitrage Fund'!$D$12:D46) -> 316264.9 | D28: ='Arbitrage Fund'!F47 -> 0.38603361 | E28: ='Arbitrage Fund'!G47 -> 1.3408641 | F28: ='Arbitrage Fund'!H47 -> 3.0020475 | G28: ='Arbitrage Fund'!I47 -> 1.9167655 | H28: ='Arbitrage Fund'!J47 -> 5.8299355 | I28: ='Arbitrage Fund'!K47 -> 6.5697518 | J28: ='Arbitrage Fund'!L47 -> 6.932793 | K28: ='Arbitrage Fund'!M47 -> 6.5479746 | ... P28: ='Arbitrage Fund'!R47 -> 6.522343 | Q28: Low Risk | R28: 3 months and above
A29: CONSERVATIVE HYBRID FUND | B29: =COUNTA('Conservative Hybrid Fund'!$A$12:A29) -> 18 | C29: =SUM('Conservative Hybrid Fund'!$D$12:D29) -> 28692.195 | D29: ='Conservative Hybrid Fund'!F30 -> 2.3874139 | E29: ='Conservative Hybrid Fund'!G30 -> 0.33351821 | F29: ='Conservative Hybrid Fund'!H30 -> 0.10700642 | G29: ='Conservative Hybrid Fund'!I30 -> -0.22014263 | H29: ='Conservative Hybrid Fund'!J30 -> 3.7205085 | I29: ='Conservative Hybrid Fund'!K30 -> 6.4932836 | J29: ='Conservative Hybrid Fund'!L30 -> 9.009678 | K29: ='Conservative Hybrid Fund'!M30 -> 8.4181219 | ... P29: ='Conservative Hybrid Fund'!R30 -> 8.8121181 | Q29: Moderately High Risk | R29: 3 years and above
A30: AGGRESSIVE HYBRID FUND | B30: =COUNTA('Aggressive Hybrid Fund'!$A$12:A40) -> 29 | C30: =SUM('Aggressive Hybrid Fund'!$D$12:D40) -> 232271.45 | D30: ='Aggressive Hybrid Fund'!F41 -> 7.6163049 | E30: ='Aggressive Hybrid Fund'!G41 -> -0.59283167 | F30: ='Aggressive Hybrid Fund'!H41 -> -2.9346608 | G30: ='Aggressive Hybrid Fund'!I41 -> -2.9265187 | H30: ='Aggressive Hybrid Fund'!J41 -> 4.1078665 | I30: ='Aggressive Hybrid Fund'!K41 -> 6.998415 | J30: ='Aggressive Hybrid Fund'!L41 -> 14.012681 | K30: ='Aggressive Hybrid Fund'!M41 -> 11.763209 | ... P30: ='Aggressive Hybrid Fund'!R41 -> 13.895832 | Q30: High Risk | R30: 5 years & above
A31: DYNAMIC ASSET ALLOCATION | B31: =COUNTA('Dynamic Asset Allocation'!$A$12:A27) -> 16 | C31: =SUM('Dynamic Asset Allocation'!$D$12:D27) -> 37266.174 | D31: ='Dynamic Asset Allocation'!F28 -> 4.8642424 | E31: ='Dynamic Asset Allocation'!G28 -> -0.9786927 | F31: ='Dynamic Asset Allocation'!H28 -> -2.4011682 | G31: ='Dynamic Asset Allocation'!I28 -> -2.6562467 | H31: ='Dynamic Asset Allocation'!J28 -> 2.6507188 | I31: ='Dynamic Asset Allocation'!K28 -> 4.9470138 | J31: ='Dynamic Asset Allocation'!L28 -> 10.681231 | K31: ='Dynamic Asset Allocation'!M28 -> 8.7216101 | ... P31: ='Dynamic Asset Allocation'!R28 -> 9.4508622 | Q31: High Risk | R31: 5 years & above
A32: BALANCED ADVANTAGE FUND | B32: =COUNTA('Balanced Advantage'!$A$12:A32) -> 21 | C32: =SUM('Balanced Advantage'!$D$12:D32) -> 268035.58 | D32: ='Balanced Advantage'!F33 -> 5.9049473 | E32: ='Balanced Advantage'!G33 -> -1.4483063 | F32: ='Balanced Advantage'!H33 -> -2.0691659 | G32: ='Balanced Advantage'!I33 -> -2.9181291 | H32: ='Balanced Advantage'!J33 -> 3.8616497 | I32: ='Balanced Advantage'!K33 -> 6.0305338 | J32: ='Balanced Advantage'!L33 -> 13.109438 | K32: ='Balanced Advantage'!M33 -> 12.431201 | ... P32: ='Balanced Advantage'!R33 -> 12.743303 | Q32: High Risk | R32: 5 years & above
A33: BALANCED HYBRID FUND | B33: =COUNTA('Balanced Hybrid'!$A$12:A19) -> 8 | C33: =SUM('Balanced Hybrid'!$D$12:D19) -> 8357.2743 | D33: ='Balanced Hybrid'!F20 -> 3.3640252 | E33: ='Balanced Hybrid'!G20 -> 1.1851306 | F33: ='Balanced Hybrid'!H20 -> 2.3993399 | G33: ='Balanced Hybrid'!I20 -> 0.58183722 | H33: ='Balanced Hybrid'!J20 -> 2.6752259 | I33: ='Balanced Hybrid'!K20 -> 5.81279 | J33: ='Balanced Hybrid'!L20 -> #DIV/0! | K33: ='Balanced Hybrid'!M20 -> #DIV/0! | ... P33: ='Balanced Hybrid'!R20 -> 5.9348923 | Q33: High Risk | R33: 5 years & above
A34: EQUITY SAVINGS | B34: =COUNTA('Equity Savings'!$A$12:A35) -> 24 | C34: =SUM('Equity Savings'!$D$12:D35) -> 52215.468 | D34: ='Equity Savings'!F36 -> 2.6114186 | E34: ='Equity Savings'!G36 -> -0.24175387 | F34: ='Equity Savings'!H36 -> -0.14099753 | G34: ='Equity Savings'!I36 -> -1.0711586 | H34: ='Equity Savings'!J36 -> 4.5534241 | I34: ='Equity Savings'!K36 -> 6.2264232 | J34: ='Equity Savings'!L36 -> 9.2913251 | K34: ='Equity Savings'!M36 -> 8.3564707 | ... P34: ='Equity Savings'!R36 -> 8.267142 | Q34: Moderate Risk | R34: 3 years & above
A35: MULTI ASSET ALLOCATION | B35: =COUNTA('Multi Asset Allocation'!$A$12:A45) -> 34 | C35: =SUM('Multi Asset Allocation'!$D$12:D45) -> 190131.77 | D35: ='Multi Asset Allocation'!F46 -> 5.91913 | E35: ='Multi Asset Allocation'!G46 -> -2.1312043 | F35: ='Multi Asset Allocation'!H46 -> 2.3641828 | G35: ='Multi Asset Allocation'!I46 -> -0.8070121 | H35: ='Multi Asset Allocation'!J46 -> 13.283958 | I35: ='Multi Asset Allocation'!K46 -> 11.833144 | J35: ='Multi Asset Allocation'!L46 -> 17.723547 | K35: ='Multi Asset Allocation'!M46 -> 15.742604 | ... P35: ='Multi Asset Allocation'!R46 -> 16.755659 | Q35: High Risk | R35: 5 years & above
A36: SOLUTION ORIENTED FUNDS
A37: RETIREMENT FUND | B37: =COUNTA('Retirement Fund'!$A$12:A41) -> 29 | C37: =SUM('Retirement Fund'!$D$12:D41) -> 29365.849 | D37: ='Retirement Fund'!F42 -> 8.2195103 | E37: ='Retirement Fund'!G42 -> -1.4903603 | F37: ='Retirement Fund'!H42 -> -3.9273743 | G37: ='Retirement Fund'!I42 -> -3.8227414 | H37: ='Retirement Fund'!J42 -> 2.8911129 | I37: ='Retirement Fund'!K42 -> 4.8892269 | J37: ='Retirement Fund'!L42 -> 13.625051 | K37: ='Retirement Fund'!M42 -> 12.174144 | ... P37: ='Retirement Fund'!R42 -> 13.047159 | Q37: -- | R37: --
A38: CHILDRENS FUNDS | B38: =COUNTA('Childrens Funds'!$A$12:A23) -> 12 | C38: =SUM('Childrens Funds'!$D$12:D23) -> 23680.665 | D38: ='Childrens Funds'!F24 -> 8.2546376 | E38: ='Childrens Funds'!G24 -> -0.34609214 | F38: ='Childrens Funds'!H24 -> -3.3071288 | G38: ='Childrens Funds'!I24 -> -2.771338 | H38: ='Childrens Funds'!J24 -> 4.4030584 | I38: ='Childrens Funds'!K24 -> 6.4217826 | J38: ='Childrens Funds'!L24 -> 13.629282 | K38: ='Childrens Funds'!M24 -> 12.167997 | ... P38: ='Childrens Funds'!R24 -> 16.870995 | Q38: -- | R38: --
A39: EQUITY FUNDS
A40: MULTI CAP FUND | B40: =COUNTA('Multi Cap Fund'!$A$12:A43) -> 32 | C40: =SUM('Multi Cap Fund'!$D$12:D43) -> 201314.63 | D40: ='Multi Cap Fund'!F44 -> 11.696746 | E40: ='Multi Cap Fund'!G44 -> 1.5328805 | F40: ='Multi Cap Fund'!H44 -> -3.8070371 | G40: ='Multi Cap Fund'!I44 -> -2.3902283 | H40: ='Multi Cap Fund'!J44 -> 6.2765106 | I40: ='Multi Cap Fund'!K44 -> 5.9915714 | J40: ='Multi Cap Fund'!L44 -> 19.008077 | K40: ='Multi Cap Fund'!M44 -> 16.320301 | ... P40: ='Multi Cap Fund'!R44 -> 14.831759 | Q40: Very High Risk | R40: 5 years & above
A41: FLEXI CAP FUND | B41: =COUNTA('Flexi Cap Fund'!$A$12:A54) -> 43 | C41: =SUM('Flexi Cap Fund'!$D$12:D54) -> 504339.78 | D41: ='Flexi Cap Fund'!F55 -> 8.5565035 | E41: ='Flexi Cap Fund'!G55 -> -2.6766087 | F41: ='Flexi Cap Fund'!H55 -> -5.482381 | G41: ='Flexi Cap Fund'!I55 -> -4.9709928 | H41: ='Flexi Cap Fund'!J55 -> 2.8068011 | I41: ='Flexi Cap Fund'!K55 -> 6.522511 | J41: ='Flexi Cap Fund'!L55 -> 16.180062 | K41: ='Flexi Cap Fund'!M55 -> 13.906942 | ... P41: ='Flexi Cap Fund'!R55 -> 15.934371 | Q41: Very High Risk | R41: 5 years & above
A42: LARGE CAP FUND | B42: =COUNTA('Large Cap Fund'!$A$12:A45) -> 34 | C42: =SUM('Large Cap Fund'!$D$12:D45) -> 367888.15 | D42: ='Large Cap Fund'!F46 -> 7.9215138 | E42: ='Large Cap Fund'!G46 -> -4.1328772 | F42: ='Large Cap Fund'!H46 -> -6.329386 | G42: ='Large Cap Fund'!I46 -> -6.939118 | H42: ='Large Cap Fund'!J46 -> 0.33237781 | I42: ='Large Cap Fund'!K46 -> 4.3173211 | J42: ='Large Cap Fund'!L46 -> 13.191695 | K42: ='Large Cap Fund'!M46 -> 11.712268 | ... P42: ='Large Cap Fund'!R46 -> 13.919457 | Q42: Very High Risk | R42: 5 years & above
A43: LARGE & MID CAP FUND | B43: =COUNTA('Large & Mid Cap Fund'!$A$12:A44) -> 33 | C43: =SUM('Large & Mid Cap Fund'!$D$12:D44) -> 299876.38 | D43: ='Large & Mid Cap Fund'!F45 -> 10.345332 | E43: ='Large & Mid Cap Fund'!G45 -> -0.7974009 | F43: ='Large & Mid Cap Fund'!H45 -> -4.075991 | G43: ='Large & Mid Cap Fund'!I45 -> -3.7412171 | H43: ='Large & Mid Cap Fund'!J45 -> 5.9366458 | I43: ='Large & Mid Cap Fund'!K45 -> 6.7070286 | J43: ='Large & Mid Cap Fund'!L45 -> 17.774746 | K43: ='Large & Mid Cap Fund'!M45 -> 14.744133 | ... P43: ='Large & Mid Cap Fund'!R45 -> 15.870797 | Q43: Very High Risk | R43: 5 years & above
A44: MID CAP FUND | B44: =COUNTA('Mid Cap Fund'!$A$12:A42) -> 31 | C44: =SUM('Mid Cap Fund'!$D$12:D42) -> 418987.58 | D44: ='Mid Cap Fund'!F43 -> 11.846896 | E44: ='Mid Cap Fund'!G43 -> 1.9883406 | F44: ='Mid Cap Fund'!H43 -> -2.297054 | G44: ='Mid Cap Fund'!I43 -> -1.2981203 | H44: ='Mid Cap Fund'!J43 -> 10.018814 | I44: ='Mid Cap Fund'!K43 -> 9.221867 | J44: ='Mid Cap Fund'!L43 -> 21.817156 | K44: ='Mid Cap Fund'!M43 -> 17.842843 | ... P44: ='Mid Cap Fund'!R43 -> 17.506018 | Q44: Very High Risk | R44: 5 years & above
...

Sheet Overnight Fund
A1: Main Page | E1: Data Source: ACEMF | CA1: Quartile code | CB1: 7 Days | CC1: 14 Days | CD1: 21 Days | CE1: 1 Month | CF1: 3 Month | CG1: 6 Months | CH1: YTD | CI1: 1 Year | CJ1: 2 Year | CK1: 3 Year | CL1: 4 Years | CM1: 5 Years | CN1: 7 Years | CO1: 10 Years | CP1: 15 Years | CQ1: Inception
CA2: 0 | CB2: =_xlfn.QUARTILE.INC(F$12:F$48,$CA2) -> 4.6846 | CC2: =_xlfn.QUARTILE.INC(G$12:G$48,$CA2) -> 4.6803 | CD2: =_xlfn.QUARTILE.INC(H$12:H$48,$CA2) -> 4.5315 | CE2: =_xlfn.QUARTILE.INC(I$12:I$48,$CA2) -> 4.4993 | CF2: =_xlfn.QUARTILE.INC(J$12:J$48,$CA2) -> 4.4888 | CG2: =_xlfn.QUARTILE.INC(K$12:K$48,$CA2) -> 4.6815 | CH2: =_xlfn.QUARTILE.INC(L$12:L$48,$CA2) -> 4.5711 | CI2: =_xlfn.QUARTILE.INC(M$12:M$48,$CA2) -> 4.9267 | ... CQ2: =_xlfn.QUARTILE.INC(U$12:U$48,$CA2) -> 4.825
CA3: 1 | CB3: =_xlfn.QUARTILE.INC(F$12:F$48,$CA3) -> 4.84975 | CC3: =_xlfn.QUARTILE.INC(G$12:G$48,$CA3) -> 4.84805 | CD3: =_xlfn.QUARTILE.INC(H$12:H$48,$CA3) -> 4.79775 | CE3: =_xlfn.QUARTILE.INC(I$12:I$48,$CA3) -> 4.9181 | CF3: =_xlfn.QUARTILE.INC(J$12:J$48,$CA3) -> 4.867 | CG3: =_xlfn.QUARTILE.INC(K$12:K$48,$CA3) -> 5.0508 | CH3: =_xlfn.QUARTILE.INC(L$12:L$48,$CA3) -> 4.93475 | CI3: =_xlfn.QUARTILE.INC(M$12:M$48,$CA3) -> 5.268725 | ... CQ3: =_xlfn.QUARTILE.INC(U$12:U$48,$CA3) -> 5.01595
CA4: 2 | CB4: =_xlfn.QUARTILE.INC(F$12:F$48,$CA4) -> 4.8991 | CC4: =_xlfn.QUARTILE.INC(G$12:G$48,$CA4) -> 4.8905 | CD4: =_xlfn.QUARTILE.INC(H$12:H$48,$CA4) -> 4.8663 | CE4: =_xlfn.QUARTILE.INC(I$12:I$48,$CA4) -> 5.0043 | CF4: =_xlfn.QUARTILE.INC(J$12:J$48,$CA4) -> 4.9435 | CG4: =_xlfn.QUARTILE.INC(K$12:K$48,$CA4) -> 5.1061 | CH4: =_xlfn.QUARTILE.INC(L$12:L$48,$CA4) -> 5.0136 | CI4: =_xlfn.QUARTILE.INC(M$12:M$48,$CA4) -> 5.3073 | ... CQ4: =_xlfn.QUARTILE.INC(U$12:U$48,$CA4) -> 5.0823
CA5: 3 | CB5: =_xlfn.QUARTILE.INC(F$12:F$48,$CA5) -> 4.9409 | CC5: =_xlfn.QUARTILE.INC(G$12:G$48,$CA5) -> 4.93095 | CD5: =_xlfn.QUARTILE.INC(H$12:H$48,$CA5) -> 4.9063 | CE5: =_xlfn.QUARTILE.INC(I$12:I$48,$CA5) -> 5.0422 | CF5: =_xlfn.QUARTILE.INC(J$12:J$48,$CA5) -> 4.98285 | CG5: =_xlfn.QUARTILE.INC(K$12:K$48,$CA5) -> 5.13935 | CH5: =_xlfn.QUARTILE.INC(L$12:L$48,$CA5) -> 5.04955 | CI5: =_xlfn.QUARTILE.INC(M$12:M$48,$CA5) -> 5.337625 | ... CQ5: =_xlfn.QUARTILE.INC(U$12:U$48,$CA5) -> 5.85415
CB6: =_xlfn.QUARTILE.INC(F$12:F$48,$CA6) -> 4.6846 | CC6: =_xlfn.QUARTILE.INC(G$12:G$48,$CA6) -> 4.6803 | CD6: =_xlfn.QUARTILE.INC(H$12:H$48,$CA6) -> 4.5315 | CE6: =_xlfn.QUARTILE.INC(I$12:I$48,$CA6) -> 4.4993 | CF6: =_xlfn.QUARTILE.INC(J$12:J$48,$CA6) -> 4.4888 | CG6: =_xlfn.QUARTILE.INC(K$12:K$48,$CA6) -> 4.6815 | CH6: =_xlfn.QUARTILE.INC(L$12:L$48,$CA6) -> 4.5711 | CI6: =_xlfn.QUARTILE.INC(M$12:M$48,$CA6) -> 4.9267 | ... CQ6: =_xlfn.QUARTILE.INC(U$12:U$48,$CA6) -> 4.825
A7: Fund Barometer - Overnight Fund | CA7: 4 | CB7: =_xlfn.QUARTILE.INC(F$12:F$48,$CA7) -> 5.0353 | CC7: =_xlfn.QUARTILE.INC(G$12:G$48,$CA7) -> 5.0483 | CD7: =_xlfn.QUARTILE.INC(H$12:H$48,$CA7) -> 4.952 | CE7: =_xlfn.QUARTILE.INC(I$12:I$48,$CA7) -> 5.1492 | CF7: =_xlfn.QUARTILE.INC(J$12:J$48,$CA7) -> 5.0749 | CG7: =_xlfn.QUARTILE.INC(K$12:K$48,$CA7) -> 5.231 | CH7: =_xlfn.QUARTILE.INC(L$12:L$48,$CA7) -> 5.1515 | CI7: =_xlfn.QUARTILE.INC(M$12:M$48,$CA7) -> 5.4694 | ... CQ7: =_xlfn.QUARTILE.INC(U$12:U$48,$CA7) -> 6.4118
A8: ='Money Market Fund'!A8 -> (As on 30 Apr 2026) | B8: Value Information | F8: Simple Annualized (%) | M8: Compound Annualized (%) | U8: Since Inception | V8: Quartile | AL8: Credit Quality | AO8: Modified Duration (Years) | AP8: Average Maturity (Years) | AQ8: YTM | AR8: Expense Ratio(%)
A9: Scheme Name | B9: Launch Date | C9: Fund Size (Rs Crs) Feb26 | D9: Fund Size (Rs Crs) Mar26 | E9: Latest NAV(Rs) | F9: 7 Days | G9: 14 Days | H9: 21 Days | I9: 1 Month | J9: 3 Months | K9: 6 Months | L9: YTD | M9: 1 Year | N9: 2 Years | O9: 3 Years | P9: 4 Years | Q9: 5 Years | R9: 7 Years | S9: 10 Years | T9: 15 Years | V9: 7 Days | W9: 14 Days | X9: 21 Days | Y9: 1 Month | Z9: 3 Months | AA9: 6 Months | AB9: YTD | AC9: 1 Year | AD9: 2 Years | AE9: 3 Years | AF9: 4 Years | AG9: 5 Years | AH9: 7 Years | AI9: 10 Years | AJ9: 15 Years | AK9: Since Inception | AL9: AA minus and Above | AM9: Below AA minus | AN9: Cash & Cash Equivalent
A10: To view Exit Loads of any Scheme in this group please click here
A11: Overnight Fund
A12: 360 ONE Overnight Fund-Reg(G) | B12: 45848 | C12: 316.1342 | D12: 443.5598 | E12: 1043.0495 | F12: 4.9533 | G12: 5.0483 | H12: 4.952 | I12: 5.0611 | J12: 5.0247 | K12: 5.2046 | L12: 5.1009 | U12: 5.3721 | V12: =IF(F12="",0,IF(F12<=CB$3,4,IF(F12>=CB$5,1,IF(F12>=CB$4,2,3)))) -> 1 | W12: =IF(G12="",0,IF(G12<=CC$3,4,IF(G12>=CC$5,1,IF(G12>=CC$4,2,3)))) -> 1 | X12: =IF(H12="",0,IF(H12<=CD$3,4,IF(H12>=CD$5,1,IF(H12>=CD$4,2,3)))) -> 1 | Y12: =IF(I12="",0,IF(I12<=CE$3,4,IF(I12>=CE$5,1,IF(I12>=CE$4,2,3)))) -> 1 | Z12: =IF(J12="",0,IF(J12<=CF$3,4,IF(J12>=CF$5,1,IF(J12>=CF$4,2,3)))) -> 1 | AA12: =IF(K12="",0,IF(K12<=CG$3,4,IF(K12>=CG$5,1,IF(K12>=CG$4,2,3)))) -> 1 | AB12: =IF(L12="",0,IF(L12<=CH$3,4,IF(L12>=CH$5,1,IF(L12>=CH$4,2,3)))) -> 1 | AC12: =IF(M12="",0,IF(M12<=CI$3,4,IF(M12>=CI$5,1,IF(M12>=CI$4,2,3)))) -> 0 | ... AK12: =IF(U12="",0,IF(U12<=CQ$3,4,IF(U12>=CQ$5,1,IF(U12>=CQ$4,2,3)))) -> 2 | AL12: 11.2692 | AN12: 88.7308 | AP12: 0.006 | AQ12: 7.61 | AR12: 0.15
A13: Aditya Birla SL Overnight Fund-Reg(G) | B13: 43405 | C13: 9405.2675 | D13: 4930.5333 | E13: 1450.2454 | F13: 4.8613 | G13: 4.8579 | H13: 4.818 | I13: 4.9739 | J13: 4.9138 | K13: 5.078 | L13: 4.9895 | M13: 5.2849 | N13: 5.8782 | O13: 6.1443 | P13: 6.0098 | Q13: 5.4447 | R13: 4.997 | U13: 5.0823 | V13: =IF(F13="",0,IF(F13<=CB$3,4,IF(F13>=CB$5,1,IF(F13>=CB$4,2,3)))) -> 3 | W13: =IF(G13="",0,IF(G13<=CC$3,4,IF(G13>=CC$5,1,IF(G13>=CC$4,2,3)))) -> 3 | X13: =IF(H13="",0,IF(H13<=CD$3,4,IF(H13>=CD$5,1,IF(H13>=CD$4,2,3)))) -> 3 | Y13: =IF(I13="",0,IF(I13<=CE$3,4,IF(I13>=CE$5,1,IF(I13>=CE$4,2,3)))) -> 3 | Z13: =IF(J13="",0,IF(J13<=CF$3,4,IF(J13>=CF$5,1,IF(J13>=CF$4,2,3)))) -> 3 | AA13: =IF(K13="",0,IF(K13<=CG$3,4,IF(K13>=CG$5,1,IF(K13>=CG$4,2,3)))) -> 3 | AB13: =IF(L13="",0,IF(L13<=CH$3,4,IF(L13>=CH$5,1,IF(L13>=CH$4,2,3)))) -> 3 | AC13: =IF(M13="",0,IF(M13<=CI$3,4,IF(M13>=CI$5,1,IF(M13>=CI$4,2,3)))) -> 3 | ... AK13: =IF(U13="",0,IF(U13<=CQ$3,4,IF(U13>=CQ$5,1,IF(U13>=CQ$4,2,3)))) -> 2 | AL13: 11.6352 | AN13: 88.3648 | AO13: 0.01 | AP13: 0.01 | AQ13: 6.95 | AR13: 0.19
A14: Axis Overnight Fund-Reg(G) | B14: 43539 | C14: 10565.678 | D14: 7849.1927 | E14: 1426.3331 | F14: 4.9677 | G14: 4.9571 | H14: 4.9206 | I14: 5.1004 | J14: 5.0444 | K14: 5.1944 | L14: 5.1154 | M14: 5.3978 | N14: 5.9861 | O14: 6.247 | P14: 6.1067 | Q14: 5.5354 | R14: 5.0845 | U14: 5.1055 | V14: =IF(F14="",0,IF(F14<=CB$3,4,IF(F14>=CB$5,1,IF(F14>=CB$4,2,3)))) -> 1 | W14: =IF(G14="",0,IF(G14<=CC$3,4,IF(G14>=CC$5,1,IF(G14>=CC$4,2,3)))) -> 1 | X14: =IF(H14="",0,IF(H14<=CD$3,4,IF(H14>=CD$5,1,IF(H14>=CD$4,2,3)))) -> 1 | Y14: =IF(I14="",0,IF(I14<=CE$3,4,IF(I14>=CE$5,1,IF(I14>=CE$4,2,3)))) -> 1 | Z14: =IF(J14="",0,IF(J14<=CF$3,4,IF(J14>=CF$5,1,IF(J14>=CF$4,2,3)))) -> 1 | AA14: =IF(K14="",0,IF(K14<=CG$3,4,IF(K14>=CG$5,1,IF(K14>=CG$4,2,3)))) -> 1 | AB14: =IF(L14="",0,IF(L14<=CH$3,4,IF(L14>=CH$5,1,IF(L14>=CH$4,2,3)))) -> 1 | AC14: =IF(M14="",0,IF(M14<=CI$3,4,IF(M14>=CI$5,1,IF(M14>=CI$4,2,3)))) -> 1 | ... AK14: =IF(U14="",0,IF(U14<=CQ$3,4,IF(U14>=CQ$5,1,IF(U14>=CQ$4,2,3)))) -> 2 | AL14: 9.3436 | AN14: 90.6564 | AO14: 0.0082 | AP14: 0.0082 | AQ14: 7.24 | AR14: 0.1
A15: Bajaj Finserv Overnight Fund-Reg(G) | B15: 45112 | C15: 1256.7598 | D15: 348.7189 | E15: 1184.9619 | F15: 4.9728 | G15: 4.9618 | H15: 4.9175 | I15: 5.0159 | J15: 4.9917 | K15: 5.2219 | L15: 5.0693 | M15: 5.4055 | N15: 5.9672 | U15: 6.1916 | V15: =IF(F15="",0,IF(F15<=CB$3,4,IF(F15>=CB$5,1,IF(F15>=CB$4,2,3)))) -> 1 | W15: =IF(G15="",0,IF(G15<=CC$3,4,IF(G15>=CC$5,1,IF(G15>=CC$4,2,3)))) -> 1 | X15: =IF(H15="",0,IF(H15<=CD$3,4,IF(H15>=CD$5,1,IF(H15>=CD$4,2,3)))) -> 1 | Y15: =IF(I15="",0,IF(I15<=CE$3,4,IF(I15>=CE$5,1,IF(I15>=CE$4,2,3)))) -> 2 | Z15: =IF(J15="",0,IF(J15<=CF$3,4,IF(J15>=CF$5,1,IF(J15>=CF$4,2,3)))) -> 1 | AA15: =IF(K15="",0,IF(K15<=CG$3,4,IF(K15>=CG$5,1,IF(K15>=CG$4,2,3)))) -> 1 | AB15: =IF(L15="",0,IF(L15<=CH$3,4,IF(L15>=CH$5,1,IF(L15>=CH$4,2,3)))) -> 1 | AC15: =IF(M15="",0,IF(M15<=CI$3,4,IF(M15>=CI$5,1,IF(M15>=CI$4,2,3)))) -> 1 | ... AK15: =IF(U15="",0,IF(U15<=CQ$3,4,IF(U15>=CQ$5,1,IF(U15>=CQ$4,2,3)))) -> 1 | AL15: 30.0779 | AN15: 69.9221 | AO15: 0.011 | AP15: 0.011 | AQ15: 6.48 | AR15: 0.13
A16: Bandhan Overnight Fund-Reg(G) | B16: 43483 | C16: 891.1468 | D16: 556.6238 | E16: 1431.1249 | F16: 4.9004 | G16: 4.8905 | H16: 4.8616 | I16: 4.9782 | J16: 4.9261 | K16: 5.0921 | L16: 4.9981 | M16: 5.3033 | N16: 5.8895 | O16: 6.1528 | P16: 6.0156 | Q16: 5.4468 | R16: 4.9913 | U16: 5.0436 | V16: =IF(F16="",0,IF(F16<=CB$3,4,IF(F16>=CB$5,1,IF(F16>=CB$4,2,3)))) -> 2 | W16: =IF(G16="",0,IF(G16<=CC$3,4,IF(G16>=CC$5,1,IF(G16>=CC$4,2,3)))) -> 2 | X16: =IF(H16="",0,IF(H16<=CD$3,4,IF(H16>=CD$5,1,IF(H16>=CD$4,2,3)))) -> 3 | Y16: =IF(I16="",0,IF(I16<=CE$3,4,IF(I16>=CE$5,1,IF(I16>=CE$4,2,3)))) -> 3 | Z16: =IF(J16="",0,IF(J16<=CF$3,4,IF(J16>=CF$5,1,IF(J16>=CF$4,2,3)))) -> 3 | AA16: =IF(K16="",0,IF(K16<=CG$3,4,IF(K16>=CG$5,1,IF(K16>=CG$4,2,3)))) -> 3 | AB16: =IF(L16="",0,IF(L16<=CH$3,4,IF(L16>=CH$5,1,IF(L16>=CH$4,2,3)))) -> 3 | AC16: =IF(M16="",0,IF(M16<=CI$3,4,IF(M16>=CI$5,1,IF(M16>=CI$4,2,3)))) -> 3 | ... AK16: =IF(U16="",0,IF(U16<=CQ$3,4,IF(U16>=CQ$5,1,IF(U16>=CQ$4,2,3)))) -> 3 | AL16: 8.9701 | AN16: 91.0299 | AO16: 0.011 | AP16: 0.011 | AQ16: 6.7 | AR16: 0.15
A17: Bank of India Overnight Fund-Reg(G) | B17: 43858 | C17: 81.6952 | D17: 36.6657 | E17: 1369.4937 | F17: 4.9155 | G17: 4.9054 | H17: 4.9148 | I17: 5.0825 | J17: 5.0749 | K17: 5.2295 | L17: 5.1308 | M17: 5.4694 | N17: 6.0592 | O17: 6.319 | P17: 6.1772 | Q17: 5.6083 | U17: 5.1513 | V17: =IF(F17="",0,IF(F17<=CB$3,4,IF(F17>=CB$5,1,IF(F17>=CB$4,2,3)))) -> 2 | W17: =IF(G17="",0,IF(G17<=CC$3,4,IF(G17>=CC$5,1,IF(G17>=CC$4,2,3)))) -> 2 | X17: =IF(H17="",0,IF(H17<=CD$3,4,IF(H17>=CD$5,1,IF(H17>=CD$4,2,3)))) -> 1 | Y17: =IF(I17="",0,IF(I17<=CE$3,4,IF(I17>=CE$5,1,IF(I17>=CE$4,2,3)))) -> 1 | Z17: =IF(J17="",0,IF(J17<=CF$3,4,IF(J17>=CF$5,1,IF(J17>=CF$4,2,3)))) -> 1 | AA17: =IF(K17="",0,IF(K17<=CG$3,4,IF(K17>=CG$5,1,IF(K17>=CG$4,2,3)))) -> 1 | AB17: =IF(L17="",0,IF(L17<=CH$3,4,IF(L17>=CH$5,1,IF(L17>=CH$4,2,3)))) -> 1 | AC17: =IF(M17="",0,IF(M17<=CI$3,4,IF(M17>=CI$5,1,IF(M17>=CI$4,2,3)))) -> 1 | ... AK17: =IF(U17="",0,IF(U17<=CQ$3,4,IF(U17>=CQ$5,1,IF(U17>=CQ$4,2,3)))) -> 2 | AL17: 8.1725 | AN17: 91.8275 | AO17: 0.0027 | AP17: 0.0027 | AQ17: 7.53 | AR17: 0.1
A18: Baroda BNP Paribas Overnight Fund-Reg(G) | B18: 43580 | C18: 766.2343 | D18: 389.2413 | E18: 1413.9736 | F18: 4.9735 | G18: 4.9629 | H18: 4.9029 | I18: 5.0302 | J18: 4.9657 | K18: 5.1359 | L18: 5.0371 | M18: 5.3371 | N18: 5.9219 | O18: 6.1829 | P18: 6.0506 | Q18: 5.4844 | R18: 5.0537 | U18: 5.0564 | V18: =IF(F18="",0,IF(F18<=CB$3,4,IF(F18>=CB$5,1,IF(F18>=CB$4,2,3)))) -> 1 | W18: =IF(G18="",0,IF(G18<=CC$3,4,IF(G18>=CC$5,1,IF(G18>=CC$4,2,3)))) -> 1 | X18: =IF(H18="",0,IF(H18<=CD$3,4,IF(H18>=CD$5,1,IF(H18>=CD$4,2,3)))) -> 2 | Y18: =IF(I18="",0,IF(I18<=CE$3,4,IF(I18>=CE$5,1,IF(I18>=CE$4,2,3)))) -> 2 | Z18: =IF(J18="",0,IF(J18<=CF$3,4,IF(J18>=CF$5,1,IF(J18>=CF$4,2,3)))) -> 2 | AA18: =IF(K18="",0,IF(K18<=CG$3,4,IF(K18>=CG$5,1,IF(K18>=CG$4,2,3)))) -> 2 | AB18: =IF(L18="",0,IF(L18<=CH$3,4,IF(L18>=CH$5,1,IF(L18>=CH$4,2,3)))) -> 2 | AC18: =IF(M18="",0,IF(M18<=CI$3,4,IF(M18>=CI$5,1,IF(M18>=CI$4,2,3)))) -> 2 | ... AK18: =IF(U18="",0,IF(U18<=CQ$3,4,IF(U18>=CQ$5,1,IF(U18>=CQ$4,2,3)))) -> 3 | AL18: 14.1059 | AN18: 85.8941 | AO18: 0.011 | AP18: 0.011 | AQ18: 6.71 | AR18: 0.13
A19: Canara Rob Overnight Fund-Reg(G) | B19: 43670 | C19: 314.9518 | D19: 264.1286 | E19: 1394.5434 | F19: 4.9537 | G19: 4.9312 | H19: 4.8828 | I19: 5.0062 | J19: 4.9422 | K19: 5.1061 | L19: 5.0105 | M19: 5.3325 | N19: 5.8925 | O19: 6.1581 | P19: 6.0344 | Q19: 5.4786 | U19: 5.03 | V19: =IF(F19="",0,IF(F19<=CB$3,4,IF(F19>=CB$5,1,IF(F19>=CB$4,2,3)))) -> 1 | W19: =IF(G19="",0,IF(G19<=CC$3,4,IF(G19>=CC$5,1,IF(G19>=CC$4,2,3)))) -> 1 | X19: =IF(H19="",0,IF(H19<=CD$3,4,IF(H19>=CD$5,1,IF(H19>=CD$4,2,3)))) -> 2 | Y19: =IF(I19="",0,IF(I19<=CE$3,4,IF(I19>=CE$5,1,IF(I19>=CE$4,2,3)))) -> 2 | Z19: =IF(J19="",0,IF(J19<=CF$3,4,IF(J19>=CF$5,1,IF(J19>=CF$4,2,3)))) -> 3 | AA19: =IF(K19="",0,IF(K19<=CG$3,4,IF(K19>=CG$5,1,IF(K19>=CG$4,2,3)))) -> 2 | AB19: =IF(L19="",0,IF(L19<=CH$3,4,IF(L19>=CH$5,1,IF(L19>=CH$4,2,3)))) -> 3 | AC19: =IF(M19="",0,IF(M19<=CI$3,4,IF(M19>=CI$5,1,IF(M19>=CI$4,2,3)))) -> 2 | ... AK19: =IF(U19="",0,IF(U19<=CQ$3,4,IF(U19>=CQ$5,1,IF(U19>=CQ$4,2,3)))) -> 3 | AL19: 7.5547 | AN19: 92.4453 | AO19: 0.01 | AP19: 0.01 | AQ19: 6.46 | AR19: 0.09
A20: DSP Overnight Fund-Reg(G) | B20: 43474 | C20: 3139.7261 | D20: 2254.6319 | E20: 1440.2778 | F20: 4.8968 | G20: 4.8897 | H20: 4.8492 | I20: 4.9959 | J20: 4.9762 | K20: 5.1389 | L20: 5.0438 | M20: 5.3342 | N20: 5.9186 | O20: 6.1867 | P20: 6.0479 | Q20: 5.4819 | R20: 5.0605 | U20: 5.1153 | V20: =IF(F20="",0,IF(F20<=CB$3,4,IF(F20>=CB$5,1,IF(F20>=CB$4,2,3)))) -> 3 | W20: =IF(G20="",0,IF(G20<=CC$3,4,IF(G20>=CC$5,1,IF(G20>=CC$4,2,3)))) -> 3 | X20: =IF(H20="",0,IF(H20<=CD$3,4,IF(H20>=CD$5,1,IF(H20>=CD$4,2,3)))) -> 3 | Y20: =IF(I20="",0,IF(I20<=CE$3,4,IF(I20>=CE$5,1,IF(I20>=CE$4,2,3)))) -> 3 | Z20: =IF(J20="",0,IF(J20<=CF$3,4,IF(J20>=CF$5,1,IF(J20>=CF$4,2,3)))) -> 2 | AA20: =IF(K20="",0,IF(K20<=CG$3,4,IF(K20>=CG$5,1,IF(K20>=CG$4,2,3)))) -> 2 | AB20: =IF(L20="",0,IF(L20<=CH$3,4,IF(L20>=CH$5,1,IF(L20>=CH$4,2,3)))) -> 2 | AC20: =IF(M20="",0,IF(M20<=CI$3,4,IF(M20>=CI$5,1,IF(M20>=CI$4,2,3)))) -> 2 | ... AK20: =IF(U20="",0,IF(U20<=CQ$3,4,IF(U20>=CQ$5,1,IF(U20>=CQ$4,2,3)))) -> 2 | AL20: 17.2757 | AN20: 82.7243 | AP20: 0.01 | AQ20: 7.13 | AR20: 0.13
A21: Edelweiss Overnight Fund-Reg(G) | B21: 43670 | C21: 210.2846 | D21: 127.253 | E21: 1393.7985 | F21: 4.9223 | G21: 4.9316 | H21: 4.9202 | I21: 5.0156 | J21: 4.958 | K21: 5.1085 | L21: 5.0279 | M21: 5.3048 | N21: 5.8778 | O21: 6.1544 | P21: 6.011 | Q21: 5.4442 | U21: 5.0224 | V21: =IF(F21="",0,IF(F21<=CB$3,4,IF(F21>=CB$5,1,IF(F21>=CB$4,2,3)))) -> 2 | W21: =IF(G21="",0,IF(G21<=CC$3,4,IF(G21>=CC$5,1,IF(G21>=CC$4,2,3)))) -> 1 | X21: =IF(H21="",0,IF(H21<=CD$3,4,IF(H21>=CD$5,1,IF(H21>=CD$4,2,3)))) -> 1 | Y21: =IF(I21="",0,IF(I21<=CE$3,4,IF(I21>=CE$5,1,IF(I21>=CE$4,2,3)))) -> 2 | Z21: =IF(J21="",0,IF(J21<=CF$3,4,IF(J21>=CF$5,1,IF(J21>=CF$4,2,3)))) -> 2 | AA21: =IF(K21="",0,IF(K21<=CG$3,4,IF(K21>=CG$5,1,IF(K21>=CG$4,2,3)))) -> 2 | AB21: =IF(L21="",0,IF(L21<=CH$3,4,IF(L21>=CH$5,1,IF(L21>=CH$4,2,3)))) -> 2 | AC21: =IF(M21="",0,IF(M21<=CI$3,4,IF(M21>=CI$5,1,IF(M21>=CI$4,2,3)))) -> 3 | ... AK21: =IF(U21="",0,IF(U21<=CQ$3,4,IF(U21>=CQ$5,1,IF(U21>=CQ$4,2,3)))) -> 3 | AL21: 3.9246 | AN21: 96.0754 | AO21: 0.0055 | AP21: 0.0055 | AQ21: 6.77 | AR21: 0.16
A22: Franklin India Overnight Fund(G) | B22: 43593 | C22: 758.3724 | D22: 527.0681 | E22: 1405.9737 | F22: 5.0353 | G22: 4.9975 | H22: 4.952 | I22: 5.1492 | J22: 5.0652 | K22: 5.231 | L22: 5.1515 | M22: 5.4121 | N22: 5.9514 | O22: 6.193 | P22: 6.0439 | Q22: 5.4724 | U22: 5 | V22: =IF(F22="",0,IF(F22<=CB$3,4,IF(F22>=CB$5,1,IF(F22>=CB$4,2,3)))) -> 1 | W22: =IF(G22="",0,IF(G22<=CC$3,4,IF(G22>=CC$5,1,IF(G22>=CC$4,2,3)))) -> 1 | X22: =IF(H22="",0,IF(H22<=CD$3,4,IF(H22>=CD$5,1,IF(H22>=CD$4,2,3)))) -> 1 | Y22: =IF(I22="",0,IF(I22<=CE$3,4,IF(I22>=CE$5,1,IF(I22>=CE$4,2,3)))) -> 1 | Z22: =IF(J22="",0,IF(J22<=CF$3,4,IF(J22>=CF$5,1,IF(J22>=CF$4,2,3)))) -> 1 | AA22: =IF(K22="",0,IF(K22<=CG$3,4,IF(K22>=CG$5,1,IF(K22>=CG$4,2,3)))) -> 1 | AB22: =IF(L22="",0,IF(L22<=CH$3,4,IF(L22>=CH$5,1,IF(L22>=CH$4,2,3)))) -> 1 | AC22: =IF(M22="",0,IF(M22<=CI$3,4,IF(M22>=CI$5,1,IF(M22>=CI$4,2,3)))) -> 1 | ... AK22: =IF(U22="",0,IF(U22<=CQ$3,4,IF(U22>=CQ$5,1,IF(U22>=CQ$4,2,3)))) -> 4 | AL22: 7.756 | AN22: 92.244 | AO22: 0.0055 | AP22: 0.0055 | AQ22: 7.62 | AR22: 0.11
A23: Groww Overnight Fund-Reg(G) | B23: 43654 | C23: 125.94 | D23: 113.2972 | E23: 1384.4933 | F23: 4.8094 | G23: 4.8076 | H23: 4.7722 | I23: 4.9064 | J23: 4.8506 | K23: 4.9915 | L23: 4.9014 | M23: 5.2051 | N23: 5.8116 | O23: 6.0409 | P23: 5.8843 | Q23: 5.3258 | U23: 4.8885 | V23: =IF(F23="",0,IF(F23<=CB$3,4,IF(F23>=CB$5,1,IF(F23>=CB$4,2,3)))) -> 4 | W23: =IF(G23="",0,IF(G23<=CC$3,4,IF(G23>=CC$5,1,IF(G23>=CC$4,2,3)))) -> 4 | X23: =IF(H23="",0,IF(H23<=CD$3,4,IF(H23>=CD$5,1,IF(H23>=CD$4,2,3)))) -> 4 | Y23: =IF(I23="",0,IF(I23<=CE$3,4,IF(I23>=CE$5,1,IF(I23>=CE$4,2,3)))) -> 4 | Z23: =IF(J23="",0,IF(J23<=CF$3,4,IF(J23>=CF$5,1,IF(J23>=CF$4,2,3)))) -> 4 | AA23: =IF(K23="",0,IF(K23<=CG$3,4,IF(K23>=CG$5,1,IF(K23>=CG$4,2,3)))) -> 4 | AB23: =IF(L23="",0,IF(L23<=CH$3,4,IF(L23>=CH$5,1,IF(L23>=CH$4,2,3)))) -> 4 | AC23: =IF(M23="",0,IF(M23<=CI$3,4,IF(M23>=CI$5,1,IF(M23>=CI$4,2,3)))) -> 4 | ... AK23: =IF(U23="",0,IF(U23<=CQ$3,4,IF(U23>=CQ$5,1,IF(U23>=CQ$4,2,3)))) -> 4 | AN23: 100 | AQ23: 7.09 | AR23: 0.24
A24: HDFC Overnight Fund(G) | B24: 37293 | C24: 10920.158 | D24: 7433.8935 | E24: 3967.7817 | F24: 4.7786 | G24: 4.7908 | H24: 4.7653 | I24: 5.0039 | J24: 4.9169 | K24: 5.0645 | L24: 4.9853 | M24: 5.2694 | N24: 5.8487 | O24: 6.1171 | P24: 5.9783 | Q24: 5.4144 | R24: 4.9683 | S24: 5.2992 | T24: 6.1562 | U24: 5.8495 | V24: =IF(F24="",0,IF(F24<=CB$3,4,IF(F24>=CB$5,1,IF(F24>=CB$4,2,3)))) -> 4 | W24: =IF(G24="",0,IF(G24<=CC$3,4,IF(G24>=CC$5,1,IF(G24>=CC$4,2,3)))) -> 4 | X24: =IF(H24="",0,IF(H24<=CD$3,4,IF(H24>=CD$5,1,IF(H24>=CD$4,2,3)))) -> 4 | Y24: =IF(I24="",0,IF(I24<=CE$3,4,IF(I24>=CE$5,1,IF(I24>=CE$4,2,3)))) -> 3 | Z24: =IF(J24="",0,IF(J24<=CF$3,4,IF(J24>=CF$5,1,IF(J24>=CF$4,2,3)))) -> 3 | AA24: =IF(K24="",0,IF(K24<=CG$3,4,IF(K24>=CG$5,1,IF(K24>=CG$4,2,3)))) -> 3 | AB24: =IF(L24="",0,IF(L24<=CH$3,4,IF(L24>=CH$5,1,IF(L24>=CH$4,2,3)))) -> 3 | AC24: =IF(M24="",0,IF(M24<=CI$3,4,IF(M24>=CI$5,1,IF(M24>=CI$4,2,3)))) -> 3 | ... AK24: =IF(U24="",0,IF(U24<=CQ$3,4,IF(U24>=CQ$5,1,IF(U24>=CQ$4,2,3)))) -> 2 | AL24: 9.3903 | AN24: 90.6097 | AO24: 0.0096 | AP24: 0.0101 | AQ24: 7.91 | AR24: 0.22
A25: Helios Overnight Fund-Reg(G) | B25: 45224 | C25: 282.5171 | D25: 257.9164 | E25: 1158.4719 | F25: 4.8372 | G25: 4.8187 | H25: 4.8076 | I25: 4.9101 | J25: 4.8036 | K25: 4.9632 | L25: 4.8783 | M25: 5.1927 | N25: 5.8032 | U25: 5.9944 | V25: =IF(F25="",0,IF(F25<=CB$3,4,IF(F25>=CB$5,1,IF(F25>=CB$4,2,3)))) -> 4 | W25: =IF(G25="",0,IF(G25<=CC$3,4,IF(G25>=CC$5,1,IF(G25>=CC$4,2,3)))) -> 4 | X25: =IF(H25="",0,IF(H25<=CD$3,4,IF(H25>=CD$5,1,IF(H25>=CD$4,2,3)))) -> 3 | Y25: =IF(I25="",0,IF(I25<=CE$3,4,IF(I25>=CE$5,1,IF(I25>=CE$4,2,3)))) -> 4 | Z25: =IF(J25="",0,IF(J25<=CF$3,4,IF(J25>=CF$5,1,IF(J25>=CF$4,2,3)))) -> 4 | AA25: =IF(K25="",0,IF(K25<=CG$3,4,IF(K25>=CG$5,1,IF(K25>=CG$4,2,3)))) -> 4 | AB25: =IF(L25="",0,IF(L25<=CH$3,4,IF(L25>=CH$5,1,IF(L25>=CH$4,2,3)))) -> 4 | AC25: =IF(M25="",0,IF(M25<=CI$3,4,IF(M25>=CI$5,1,IF(M25>=CI$4,2,3)))) -> 4 | ... AK25: =IF(U25="",0,IF(U25<=CQ$3,4,IF(U25>=CQ$5,1,IF(U25>=CQ$4,2,3)))) -> 1 | AN25: 100 | AO25: 0.0027 | AP25: 0.0027 | AQ25: 6.42 | AR25: 0.19
A26: HSBC Overnight Fund-Reg(G) | B26: 43607 | C26: 4360.5363 | D26: 2589.0747 | E26: 1403.4294 | F26: 4.8352 | G26: 4.8518 | H26: 4.8684 | I26: 5.0499 | J26: 5.0249 | K26: 5.1576 | L26: 5.0826 | M26: 5.3411 | N26: 5.9092 | O26: 6.1701 | P26: 6.0248 | Q26: 5.4588 | U26: 4.9986 | V26: =IF(F26="",0,IF(F26<=CB$3,4,IF(F26>=CB$5,1,IF(F26>=CB$4,2,3)))) -> 4 | W26: =IF(G26="",0,IF(G26<=CC$3,4,IF(G26>=CC$5,1,IF(G26>=CC$4,2,3)))) -> 3 | X26: =IF(H26="",0,IF(H26<=CD$3,4,IF(H26>=CD$5,1,IF(H26>=CD$4,2,3)))) -> 2 | Y26: =IF(I26="",0,IF(I26<=CE$3,4,IF(I26>=CE$5,1,IF(I26>=CE$4,2,3)))) -> 1 | Z26: =IF(J26="",0,IF(J26<=CF$3,4,IF(J26>=CF$5,1,IF(J26>=CF$4,2,3)))) -> 1 | AA26: =IF(K26="",0,IF(K26<=CG$3,4,IF(K26>=CG$5,1,IF(K26>=CG$4,2,3)))) -> 1 | AB26: =IF(L26="",0,IF(L26<=CH$3,4,IF(L26>=CH$5,1,IF(L26>=CH$4,2,3)))) -> 1 | AC26: =IF(M26="",0,IF(M26<=CI$3,4,IF(M26>=CI$5,1,IF(M26>=CI$4,2,3)))) -> 1 | ... AK26: =IF(U26="",0,IF(U26<=CQ$3,4,IF(U26>=CQ$5,1,IF(U26>=CQ$4,2,3)))) -> 4 | AL26: 9.4423 | AN26: 90.5577 | AO26: 0.0081 | AP26: 0.0081 | AQ26: 6.74 | AR26: 0.14
A27: ICICI Pru Overnight Fund(G) | B27: 43419 | C27: 11394.694 | D27: 8823.6046 | E27: 1448.4445 | F27: 4.8991 | G27: 4.9071 | H27: 4.8744 | I27: 5.0347 | J27: 4.9803 | K27: 5.1398 | L27: 5.0502 | M27: 5.3378 | N27: 5.913 | O27: 6.1824 | P27: 6.0366 | Q27: 5.4653 | R27: 5.0103 | U27: 5.0894 | V27: =IF(F27="",0,IF(F27<=CB$3,4,IF(F27>=CB$5,1,IF(F27>=CB$4,2,3)))) -> 2 | W27: =IF(G27="",0,IF(G27<=CC$3,4,IF(G27>=CC$5,1,IF(G27>=CC$4,2,3)))) -> 2 | X27: =IF(H27="",0,IF(H27<=CD$3,4,IF(H27>=CD$5,1,IF(H27>=CD$4,2,3)))) -> 2 | Y27: =IF(I27="",0,IF(I27<=CE$3,4,IF(I27>=CE$5,1,IF(I27>=CE$4,2,3)))) -> 2 | Z27: =IF(J27="",0,IF(J27<=CF$3,4,IF(J27>=CF$5,1,IF(J27>=CF$4,2,3)))) -> 2 | AA27: =IF(K27="",0,IF(K27<=CG$3,4,IF(K27>=CG$5,1,IF(K27>=CG$4,2,3)))) -> 1 | AB27: =IF(L27="",0,IF(L27<=CH$3,4,IF(L27>=CH$5,1,IF(L27>=CH$4,2,3)))) -> 1 | AC27: =IF(M27="",0,IF(M27<=CI$3,4,IF(M27>=CI$5,1,IF(M27>=CI$4,2,3)))) -> 1 | ... AK27: =IF(U27="",0,IF(U27<=CQ$3,4,IF(U27>=CQ$5,1,IF(U27>=CQ$4,2,3)))) -> 2 | AL27: 7.4754 | AN27: 92.5246 | AO27: 0.0062 | AP27: 0.0093 | AQ27: 7.23 | AR27: 0.15
A28: Invesco India Overnight Fund-Reg(G) | B28: 43838 | C28: 331.7019 | D28: 316.2587 | E28: 1361.617 | F28: 4.9305 | G28: 4.9198 | H28: 4.8829 | I28: 5.0361 | J28: 4.986 | K28: 5.1412 | L28: 5.0539 | M28: 5.3463 | N28: 5.9305 | O28: 6.2026 | P28: 6.0574 | Q28: 5.4877 | U28: 5.0115 | V28: =IF(F28="",0,IF(F28<=CB$3,4,IF(F28>=CB$5,1,IF(F28>=CB$4,2,3)))) -> 2 | W28: =IF(G28="",0,IF(G28<=CC$3,4,IF(G28>=CC$5,1,IF(G28>=CC$4,2,3)))) -> 2 | X28: =IF(H28="",0,IF(H28<=CD$3,4,IF(H28>=CD$5,1,IF(H28>=CD$4,2,3)))) -> 2 | Y28: =IF(I28="",0,IF(I28<=CE$3,4,IF(I28>=CE$5,1,IF(I28>=CE$4,2,3)))) -> 2 | Z28: =IF(J28="",0,IF(J28<=CF$3,4,IF(J28>=CF$5,1,IF(J28>=CF$4,2,3)))) -> 1 | AA28: =IF(K28="",0,IF(K28<=CG$3,4,IF(K28>=CG$5,1,IF(K28>=CG$4,2,3)))) -> 1 | AB28: =IF(L28="",0,IF(L28<=CH$3,4,IF(L28>=CH$5,1,IF(L28>=CH$4,2,3)))) -> 1 | AC28: =IF(M28="",0,IF(M28<=CI$3,4,IF(M28>=CI$5,1,IF(M28>=CI$4,2,3)))) -> 1 | ... AK28: =IF(U28="",0,IF(U28<=CQ$3,4,IF(U28>=CQ$5,1,IF(U28>=CQ$4,2,3)))) -> 4 | AL28: 13.5594 | AN28: 86.4406 | AO28: 0.0082 | AP28: 0.011 | AQ28: 6.97 | AR28: 0.12
A29: ITI Overnight Fund-Reg(G) | B29: 43762 | C29: 15.0267 | D29: 24.7077 | E29: 1359.7005 | F29: 4.7584 | G29: 4.741 | H29: 4.666 | I29: 4.7151 | J29: 4.6655 | K29: 4.8353 | L29: 4.7481 | M29: 5.0912 | N29: 5.659 | O29: 5.9225 | P29: 5.8044 | Q29: 5.2708 | U29: 4.825 | V29: =IF(F29="",0,IF(F29<=CB$3,4,IF(F29>=CB$5,1,IF(F29>=CB$4,2,3)))) -> 4 | W29: =IF(G29="",0,IF(G29<=CC$3,4,IF(G29>=CC$5,1,IF(G29>=CC$4,2,3)))) -> 4 | X29: =IF(H29="",0,IF(H29<=CD$3,4,IF(H29>=CD$5,1,IF(H29>=CD$4,2,3)))) -> 4 | Y29: =IF(I29="",0,IF(I29<=CE$3,4,IF(I29>=CE$5,1,IF(I29>=CE$4,2,3)))) -> 4 | Z29: =IF(J29="",0,IF(J29<=CF$3,4,IF(J29>=CF$5,1,IF(J29>=CF$4,2,3)))) -> 4 | AA29: =IF(K29="",0,IF(K29<=CG$3,4,IF(K29>=CG$5,1,IF(K29>=CG$4,2,3)))) -> 4 | AB29: =IF(L29="",0,IF(L29<=CH$3,4,IF(L29>=CH$5,1,IF(L29>=CH$4,2,3)))) -> 4 | AC29: =IF(M29="",0,IF(M29<=CI$3,4,IF(M29>=CI$5,1,IF(M29>=CI$4,2,3)))) -> 4 | ... AK29: =IF(U29="",0,IF(U29<=CQ$3,4,IF(U29>=CQ$5,1,IF(U29>=CQ$4,2,3)))) -> 4 | AN29: 100 | AO29: 0.0055 | AP29: 0.0055 | AQ29: 6.14 | AR29: 0.18
A30: JM Overnight Fund-Reg(G) | B30: 43802 | C30: 89.3495 | D30: 52.6808 | E30: 1364.521 | F30: 4.7428 | G30: 4.7133 | H30: 4.6667 | I30: 4.8126 | J30: 4.7687 | K30: 4.9571 | L30: 4.8602 | M30: 5.1937 | N30: 5.8052 | O30: 6.0918 | P30: 5.9723 | Q30: 5.4221 | U30: 4.9674 | V30: =IF(F30="",0,IF(F30<=CB$3,4,IF(F30>=CB$5,1,IF(F30>=CB$4,2,3)))) -> 4 | W30: =IF(G30="",0,IF(G30<=CC$3,4,IF(G30>=CC$5,1,IF(G30>=CC$4,2,3)))) -> 4 | X30: =IF(H30="",0,IF(H30<=CD$3,4,IF(H30>=CD$5,1,IF(H30>=CD$4,2,3)))) -> 4 | Y30: =IF(I30="",0,IF(I30<=CE$3,4,IF(I30>=CE$5,1,IF(I30>=CE$4,2,3)))) -> 4 | Z30: =IF(J30="",0,IF(J30<=CF$3,4,IF(J30>=CF$5,1,IF(J30>=CF$4,2,3)))) -> 4 | AA30: =IF(K30="",0,IF(K30<=CG$3,4,IF(K30>=CG$5,1,IF(K30>=CG$4,2,3)))) -> 4 | AB30: =IF(L30="",0,IF(L30<=CH$3,4,IF(L30>=CH$5,1,IF(L30>=CH$4,2,3)))) -> 4 | AC30: =IF(M30="",0,IF(M30<=CI$3,4,IF(M30>=CI$5,1,IF(M30>=CI$4,2,3)))) -> 4 | ... AK30: =IF(U30="",0,IF(U30<=CQ$3,4,IF(U30>=CQ$5,1,IF(U30>=CQ$4,2,3)))) -> 4 | AN30: 100 | AO30: 0.0055 | AP30: 0.0055 | AQ30: 6.72 | AR30: 0.15
A31: Kotak Overnight Fund-Reg(G) | B31: 43480 | C31: 7093.1994 | D31: 5066.8514 | E31: 1433.4649 | F31: 4.8814 | G31: 4.8951 | H31: 4.8663 | I31: 5.0253 | J31: 4.9778 | K31: 5.1309 | L31: 5.0489 | M31: 5.3355 | N31: 5.9199 | O31: 6.1728 | P31: 6.0267 | Q31: 5.4573 | R31: 5.0113 | U31: 5.0614 | V31: =IF(F31="",0,IF(F31<=CB$3,4,IF(F31>=CB$5,1,IF(F31>=CB$4,2,3)))) -> 3 | W31: =IF(G31="",0,IF(G31<=CC$3,4,IF(G31>=CC$5,1,IF(G31>=CC$4,2,3)))) -> 2 | X31: =IF(H31="",0,IF(H31<=CD$3,4,IF(H31>=CD$5,1,IF(H31>=CD$4,2,3)))) -> 2 | Y31: =IF(I31="",0,IF(I31<=CE$3,4,IF(I31>=CE$5,1,IF(I31>=CE$4,2,3)))) -> 2 | Z31: =IF(J31="",0,IF(J31<=CF$3,4,IF(J31>=CF$5,1,IF(J31>=CF$4,2,3)))) -> 2 | AA31: =IF(K31="",0,IF(K31<=CG$3,4,IF(K31>=CG$5,1,IF(K31>=CG$4,2,3)))) -> 2 | AB31: =IF(L31="",0,IF(L31<=CH$3,4,IF(L31>=CH$5,1,IF(L31>=CH$4,2,3)))) -> 2 | AC31: =IF(M31="",0,IF(M31<=CI$3,4,IF(M31>=CI$5,1,IF(M31>=CI$4,2,3)))) -> 2 | ... AK31: =IF(U31="",0,IF(U31<=CQ$3,4,IF(U31>=CQ$5,1,IF(U31>=CQ$4,2,3)))) -> 3 | AL31: 4.6267 | AN31: 95.3733 | AO31: 0.0068 | AP31: 0.0075 | AQ31: 7.16 | AR31: 0.16
A32: LIC MF Overnight Fund-Reg(G) | B32: 43664 | C32: 549.6373 | D32: 902.4863 | E32: 1390.3509 | F32: 4.9473 | G32: 4.9307 | H32: 4.904 | I32: 5.056 | J32: 4.9568 | K32: 5.123 | L32: 5.0336 | M32: 5.3264 | N32: 5.8893 | O32: 6.139 | P32: 6.0007 | Q32: 5.4376 | U32: 4.9655 | V32: =IF(F32="",0,IF(F32<=CB$3,4,IF(F32>=CB$5,1,IF(F32>=CB$4,2,3)))) -> 1 | W32: =IF(G32="",0,IF(G32<=CC$3,4,IF(G32>=CC$5,1,IF(G32>=CC$4,2,3)))) -> 2 | X32: =IF(H32="",0,IF(H32<=CD$3,4,IF(H32>=CD$5,1,IF(H32>=CD$4,2,3)))) -> 2 | Y32: =IF(I32="",0,IF(I32<=CE$3,4,IF(I32>=CE$5,1,IF(I32>=CE$4,2,3)))) -> 1 | Z32: =IF(J32="",0,IF(J32<=CF$3,4,IF(J32>=CF$5,1,IF(J32>=CF$4,2,3)))) -> 2 | AA32: =IF(K32="",0,IF(K32<=CG$3,4,IF(K32>=CG$5,1,IF(K32>=CG$4,2,3)))) -> 2 | AB32: =IF(L32="",0,IF(L32<=CH$3,4,IF(L32>=CH$5,1,IF(L32>=CH$4,2,3)))) -> 2 | AC32: =IF(M32="",0,IF(M32<=CI$3,4,IF(M32>=CI$5,1,IF(M32>=CI$4,2,3)))) -> 2 | ... AK32: =IF(U32="",0,IF(U32<=CQ$3,4,IF(U32>=CQ$5,1,IF(U32>=CQ$4,2,3)))) -> 4 | AL32: 4.9754 | AN32: 95.0246 | AO32: 0.0074 | AP32: 0.0074 | AQ32: 7.08 | AR32: 0.15
A33: Mahindra Manulife Overnight Fund-Reg(G) | B33: 43669 | C33: 213.6509 | D33: 27.085 | E33: 1390.3659 | F33: 4.8382 | G33: 4.8358 | H33: 4.7595 | I33: 4.8541 | J33: 4.9163 | K33: 5.0908 | L33: 4.9957 | M33: 5.3025 | N33: 5.8871 | O33: 6.148 | P33: 6.0155 | Q33: 5.4587 | U33: 4.9845 | V33: =IF(F33="",0,IF(F33<=CB$3,4,IF(F33>=CB$5,1,IF(F33>=CB$4,2,3)))) -> 4 | W33: =IF(G33="",0,IF(G33<=CC$3,4,IF(G33>=CC$5,1,IF(G33>=CC$4,2,3)))) -> 4 | X33: =IF(H33="",0,IF(H33<=CD$3,4,IF(H33>=CD$5,1,IF(H33>=CD$4,2,3)))) -> 4 | Y33: =IF(I33="",0,IF(I33<=CE$3,4,IF(I33>=CE$5,1,IF(I33>=CE$4,2,3)))) -> 4 | Z33: =IF(J33="",0,IF(J33<=CF$3,4,IF(J33>=CF$5,1,IF(J33>=CF$4,2,3)))) -> 3 | AA33: =IF(K33="",0,IF(K33<=CG$3,4,IF(K33>=CG$5,1,IF(K33>=CG$4,2,3)))) -> 3 | AB33: =IF(L33="",0,IF(L33<=CH$3,4,IF(L33>=CH$5,1,IF(L33>=CH$4,2,3)))) -> 3 | AC33: =IF(M33="",0,IF(M33<=CI$3,4,IF(M33>=CI$5,1,IF(M33>=CI$4,2,3)))) -> 3 | ... AK33: =IF(U33="",0,IF(U33<=CQ$3,4,IF(U33>=CQ$5,1,IF(U33>=CQ$4,2,3)))) -> 4 | AL33: 34.6476 | AN33: 65.3524 | AO33: 0.0166 | AP33: 0.0167 | AQ33: 6.32 | AR33: 0.19
A34: Mirae Asset Overnight Fund-Reg(G) | B34: 43753 | C34: 1530.4354 | D34: 708.1232 | E34: 1378.7749 | F34: 4.8907 | G34: 4.8898 | H34: 4.8676 | I34: 4.9638 | J34: 4.9319 | K34: 5.115 | L34: 5.0136 | M34: 5.3365 | N34: 5.9202 | O34: 6.183 | P34: 6.0461 | Q34: 5.4884 | U34: 5.0297 | V34: =IF(F34="",0,IF(F34<=CB$3,4,IF(F34>=CB$5,1,IF(F34>=CB$4,2,3)))) -> 3 | W34: =IF(G34="",0,IF(G34<=CC$3,4,IF(G34>=CC$5,1,IF(G34>=CC$4,2,3)))) -> 3 | X34: =IF(H34="",0,IF(H34<=CD$3,4,IF(H34>=CD$5,1,IF(H34>=CD$4,2,3)))) -> 2 | Y34: =IF(I34="",0,IF(I34<=CE$3,4,IF(I34>=CE$5,1,IF(I34>=CE$4,2,3)))) -> 3 | Z34: =IF(J34="",0,IF(J34<=CF$3,4,IF(J34>=CF$5,1,IF(J34>=CF$4,2,3)))) -> 3 | AA34: =IF(K34="",0,IF(K34<=CG$3,4,IF(K34>=CG$5,1,IF(K34>=CG$4,2,3)))) -> 2 | AB34: =IF(L34="",0,IF(L34<=CH$3,4,IF(L34>=CH$5,1,IF(L34>=CH$4,2,3)))) -> 2 | AC34: =IF(M34="",0,IF(M34<=CI$3,4,IF(M34>=CI$5,1,IF(M34>=CI$4,2,3)))) -> 2 | ... AK34: =IF(U34="",0,IF(U34<=CQ$3,4,IF(U34>=CQ$5,1,IF(U34>=CQ$4,2,3)))) -> 3 | AL34: 7.0572 | AN34: 92.9428 | AO34: 0.01 | AP34: 0.0072 | AQ34: 6.39 | AR34: 0.17
A35: Nippon India Overnight Fund-Reg(G) | B35: 43452 | C35: 6730.1801 | D35: 3903.1226 | E35: 144.31 | F35: 4.8969 | G35: 4.907 | H35: 4.8856 | I35: 5.0483 | J35: 4.9755 | K35: 5.1327 | L35: 5.0441 | M35: 5.3384 | N35: 5.9313 | O35: 6.1884 | P35: 6.0487 | Q35: 5.4806 | R35: 5.0383 | U35: 5.1029 | V35: =IF(F35="",0,IF(F35<=CB$3,4,IF(F35>=CB$5,1,IF(F35>=CB$4,2,3)))) -> 3 | W35: =IF(G35="",0,IF(G35<=CC$3,4,IF(G35>=CC$5,1,IF(G35>=CC$4,2,3)))) -> 2 | X35: =IF(H35="",0,IF(H35<=CD$3,4,IF(H35>=CD$5,1,IF(H35>=CD$4,2,3)))) -> 2 | Y35: =IF(I35="",0,IF(I35<=CE$3,4,IF(I35>=CE$5,1,IF(I35>=CE$4,2,3)))) -> 1 | Z35: =IF(J35="",0,IF(J35<=CF$3,4,IF(J35>=CF$5,1,IF(J35>=CF$4,2,3)))) -> 2 | AA35: =IF(K35="",0,IF(K35<=CG$3,4,IF(K35>=CG$5,1,IF(K35>=CG$4,2,3)))) -> 2 | AB35: =IF(L35="",0,IF(L35<=CH$3,4,IF(L35>=CH$5,1,IF(L35>=CH$4,2,3)))) -> 2 | AC35: =IF(M35="",0,IF(M35<=CI$3,4,IF(M35>=CI$5,1,IF(M35>=CI$4,2,3)))) -> 1 | ... AK35: =IF(U35="",0,IF(U35<=CQ$3,4,IF(U35>=CQ$5,1,IF(U35>=CQ$4,2,3)))) -> 2 | AL35: 12.7874 | AN35: 87.2126 | AO35: 0.011 | AP35: 0.011 | AQ35: 7.14 | AR35: 0.16
A36: NJ Overnight Fund-Reg(G) | B36: 44774 | C36: 409.2044 | D36: 360.8746 | E36: 1247.029 | F36: 4.8811 | G36: 4.8586 | H36: 4.7803 | I36: 4.9261 | J36: 4.8519 | K36: 4.9922 | L36: 4.9189 | M36: 5.2231 | N36: 5.8039 | O36: 6.0781 | U36: 6.0633 | V36: =IF(F36="",0,IF(F36<=CB$3,4,IF(F36>=CB$5,1,IF(F36>=CB$4,2,3)))) -> 3 | W36: =IF(G36="",0,IF(G36<=CC$3,4,IF(G36>=CC$5,1,IF(G36>=CC$4,2,3)))) -> 3 | X36: =IF(H36="",0,IF(H36<=CD$3,4,IF(H36>=CD$5,1,IF(H36>=CD$4,2,3)))) -> 4 | Y36: =IF(I36="",0,IF(I36<=CE$3,4,IF(I36>=CE$5,1,IF(I36>=CE$4,2,3)))) -> 3 | Z36: =IF(J36="",0,IF(J36<=CF$3,4,IF(J36>=CF$5,1,IF(J36>=CF$4,2,3)))) -> 4 | AA36: =IF(K36="",0,IF(K36<=CG$3,4,IF(K36>=CG$5,1,IF(K36>=CG$4,2,3)))) -> 4 | AB36: =IF(L36="",0,IF(L36<=CH$3,4,IF(L36>=CH$5,1,IF(L36>=CH$4,2,3)))) -> 4 | AC36: =IF(M36="",0,IF(M36<=CI$3,4,IF(M36>=CI$5,1,IF(M36>=CI$4,2,3)))) -> 4 | ... AK36: =IF(U36="",0,IF(U36<=CQ$3,4,IF(U36>=CQ$5,1,IF(U36>=CQ$4,2,3)))) -> 1 | AN36: 100 | AO36: 0.0055 | AP36: 0.0055 | AQ36: 6.31 | AR36: 0.15
A37: PGIM India Overnight Fund-Reg(G) | B37: 43704 | C37: 46.465 | D37: 40.8329 | E37: 1388.1307 | F37: 4.892 | G37: 4.8443 | H37: 4.8014 | I37: 4.8261 | J37: 4.8143 | K37: 5.0493 | L37: 4.9028 | M37: 5.2723 | N37: 5.9096 | O37: 6.1703 | P37: 6.0317 | Q37: 5.481 | U37: 5.0325 | V37: =IF(F37="",0,IF(F37<=CB$3,4,IF(F37>=CB$5,1,IF(F37>=CB$4,2,3)))) -> 3 | W37: =IF(G37="",0,IF(G37<=CC$3,4,IF(G37>=CC$5,1,IF(G37>=CC$4,2,3)))) -> 4 | X37: =IF(H37="",0,IF(H37<=CD$3,4,IF(H37>=CD$5,1,IF(H37>=CD$4,2,3)))) -> 3 | Y37: =IF(I37="",0,IF(I37<=CE$3,4,IF(I37>=CE$5,1,IF(I37>=CE$4,2,3)))) -> 4 | Z37: =IF(J37="",0,IF(J37<=CF$3,4,IF(J37>=CF$5,1,IF(J37>=CF$4,2,3)))) -> 4 | AA37: =IF(K37="",0,IF(K37<=CG$3,4,IF(K37>=CG$5,1,IF(K37>=CG$4,2,3)))) -> 4 | AB37: =IF(L37="",0,IF(L37<=CH$3,4,IF(L37>=CH$5,1,IF(L37>=CH$4,2,3)))) -> 4 | AC37: =IF(M37="",0,IF(M37<=CI$3,4,IF(M37>=CI$5,1,IF(M37>=CI$4,2,3)))) -> 3 | ... AK37: =IF(U37="",0,IF(U37<=CQ$3,4,IF(U37>=CQ$5,1,IF(U37>=CQ$4,2,3)))) -> 3 | AL37: 4.8823 | AN37: 95.1177 | AO37: 0.0027 | AP37: 0.0027 | AQ37: 5.53 | AR37: 0.18
A38: Quant Overnight Fund-Reg(G) | B38: 44900 | C38: 54.2887 | D38: 55.9234 | E38: 12.3166 | F38: 4.7459 | G38: 4.7502 | H38: 4.6836 | I38: 4.7222 | J38: 4.673 | K38: 4.8598 | L38: 4.7631 | M38: 5.1443 | N38: 5.8564 | O38: 6.2993 | U38: 6.3101 | V38: =IF(F38="",0,IF(F38<=CB$3,4,IF(F38>=CB$5,1,IF(F38>=CB$4,2,3)))) -> 4 | W38: =IF(G38="",0,IF(G38<=CC$3,4,IF(G38>=CC$5,1,IF(G38>=CC$4,2,3)))) -> 4 | X38: =IF(H38="",0,IF(H38<=CD$3,4,IF(H38>=CD$5,1,IF(H38>=CD$4,2,3)))) -> 4 | Y38: =IF(I38="",0,IF(I38<=CE$3,4,IF(I38>=CE$5,1,IF(I38>=CE$4,2,3)))) -> 4 | Z38: =IF(J38="",0,IF(J38<=CF$3,4,IF(J38>=CF$5,1,IF(J38>=CF$4,2,3)))) -> 4 | AA38: =IF(K38="",0,IF(K38<=CG$3,4,IF(K38>=CG$5,1,IF(K38>=CG$4,2,3)))) -> 4 | AB38: =IF(L38="",0,IF(L38<=CH$3,4,IF(L38>=CH$5,1,IF(L38>=CH$4,2,3)))) -> 4 | AC38: =IF(M38="",0,IF(M38<=CI$3,4,IF(M38>=CI$5,1,IF(M38>=CI$4,2,3)))) -> 4 | ... AK38: =IF(U38="",0,IF(U38<=CQ$3,4,IF(U38>=CQ$5,1,IF(U38>=CQ$4,2,3)))) -> 1 | AN38: 100 | AO38: 0.0082 | AP38: 0.0082 | AQ38: 5.05 | AR38: 0.24
A39: Samco Overnight Fund-Reg(G) | B39: 44846 | C39: 30.8868 | D39: 22.7412 | E39: 1225.58 | F39: 4.6846 | G39: 4.6803 | H39: 4.5315 | I39: 4.4993 | J39: 4.4888 | K39: 4.6815 | L39: 4.5711 | M39: 4.9267 | N39: 5.5223 | O39: 5.8298 | U39: 5.8962 | V39: =IF(F39="",0,IF(F39<=CB$3,4,IF(F39>=CB$5,1,IF(F39>=CB$4,2,3)))) -> 4 | W39: =IF(G39="",0,IF(G39<=CC$3,4,IF(G39>=CC$5,1,IF(G39>=CC$4,2,3)))) -> 4 | X39: =IF(H39="",0,IF(H39<=CD$3,4,IF(H39>=CD$5,1,IF(H39>=CD$4,2,3)))) -> 4 | Y39: =IF(I39="",0,IF(I39<=CE$3,4,IF(I39>=CE$5,1,IF(I39>=CE$4,2,3)))) -> 4 | Z39: =IF(J39="",0,IF(J39<=CF$3,4,IF(J39>=CF$5,1,IF(J39>=CF$4,2,3)))) -> 4 | AA39: =IF(K39="",0,IF(K39<=CG$3,4,IF(K39>=CG$5,1,IF(K39>=CG$4,2,3)))) -> 4 | AB39: =IF(L39="",0,IF(L39<=CH$3,4,IF(L39>=CH$5,1,IF(L39>=CH$4,2,3)))) -> 4 | AC39: =IF(M39="",0,IF(M39<=CI$3,4,IF(M39>=CI$5,1,IF(M39>=CI$4,2,3)))) -> 4 | ... AK39: =IF(U39="",0,IF(U39<=CQ$3,4,IF(U39>=CQ$5,1,IF(U39>=CQ$4,2,3)))) -> 1 | AN39: 100 | AO39: 0.0055 | AP39: 0.0055 | AQ39: 5.01 | AR39: 0.33
A40: SBI Overnight Fund-Reg(G) | B40: 37523 | C40: 28880.19 | D40: 17848.677 | E40: 4338.4369 | F40: 4.9312 | G40: 4.9148 | H40: 4.8611 | I40: 4.9767 | J40: 4.9298 | K40: 5.0888 | L40: 4.9997 | M40: 5.3098 | N40: 5.8886 | O40: 6.1426 | P40: 6.007 | Q40: 5.4451 | R40: 5.0051 | S40: 5.3316 | T40: 6.4202 | U40: 6.4118 | V40: =IF(F40="",0,IF(F40<=CB$3,4,IF(F40>=CB$5,1,IF(F40>=CB$4,2,3)))) -> 2 | W40: =IF(G40="",0,IF(G40<=CC$3,4,IF(G40>=CC$5,1,IF(G40>=CC$4,2,3)))) -> 2 | X40: =IF(H40="",0,IF(H40<=CD$3,4,IF(H40>=CD$5,1,IF(H40>=CD$4,2,3)))) -> 3 | Y40: =IF(I40="",0,IF(I40<=CE$3,4,IF(I40>=CE$5,1,IF(I40>=CE$4,2,3)))) -> 3 | Z40: =IF(J40="",0,IF(J40<=CF$3,4,IF(J40>=CF$5,1,IF(J40>=CF$4,2,3)))) -> 3 | AA40: =IF(K40="",0,IF(K40<=CG$3,4,IF(K40>=CG$5,1,IF(K40>=CG$4,2,3)))) -> 3 | AB40: =IF(L40="",0,IF(L40<=CH$3,4,IF(L40>=CH$5,1,IF(L40>=CH$4,2,3)))) -> 3 | AC40: =IF(M40="",0,IF(M40<=CI$3,4,IF(M40>=CI$5,1,IF(M40>=CI$4,2,3)))) -> 2 | ... AK40: =IF(U40="",0,IF(U40<=CQ$3,4,IF(U40>=CQ$5,1,IF(U40>=CQ$4,2,3)))) -> 1 | AL40: 5.9586 | AN40: 94.0414 | AO40: 0.0027 | AP40: 0.0027 | AQ40: 6.5 | AR40: 0.14
...

Sheet Money Market Fund
A1: Main Page | E1: Data Source: ACEMF | CA1: Quartile code | CB1: 7 Days | CC1: 14 Days | CD1: 21 Days | CE1: 1 Month | CF1: 3 Month | CG1: 6 Months | CH1: YTD | CI1: 1 Year | CJ1: 2 Year | CK1: 3 Year | CL1: 4 Years | CM1: 5 Years | CN1: 7 Years | CO1: 10 Years | CP1: 15 Years | CQ1: Inception
CA2: 0 | CB2: =_xlfn.QUARTILE.INC(F$12:F$36,$CA2) -> -1.9426 | CC2: =_xlfn.QUARTILE.INC(G$12:G$36,$CA2) -> -0.3119 | CD2: =_xlfn.QUARTILE.INC(H$12:H$36,$CA2) -> 2.7972 | CE2: =_xlfn.QUARTILE.INC(I$12:I$36,$CA2) -> 3.9817 | CF2: =_xlfn.QUARTILE.INC(J$12:J$36,$CA2) -> 4.7597 | CG2: =_xlfn.QUARTILE.INC(K$12:K$36,$CA2) -> 5.257 | CH2: =_xlfn.QUARTILE.INC(L$12:L$36,$CA2) -> 4.3557 | CI2: =_xlfn.QUARTILE.INC(M$12:M$36,$CA2) -> 5.7593 | ... CQ2: =_xlfn.QUARTILE.INC(U$12:U$36,$CA2) -> 4.7199
CA3: 1 | CB3: =_xlfn.QUARTILE.INC(F$12:F$36,$CA3) -> -1.5878 | CC3: =_xlfn.QUARTILE.INC(G$12:G$36,$CA3) -> 0.0722 | CD3: =_xlfn.QUARTILE.INC(H$12:H$36,$CA3) -> 3.8084 | CE3: =_xlfn.QUARTILE.INC(I$12:I$36,$CA3) -> 7.143 | CF3: =_xlfn.QUARTILE.INC(J$12:J$36,$CA3) -> 5.9717 | CG3: =_xlfn.QUARTILE.INC(K$12:K$36,$CA3) -> 5.5567 | CH3: =_xlfn.QUARTILE.INC(L$12:L$36,$CA3) -> 5.4058 | CI3: =_xlfn.QUARTILE.INC(M$12:M$36,$CA3) -> 6.035775 | ... CQ3: =_xlfn.QUARTILE.INC(U$12:U$36,$CA3) -> 6.1688
CA4: 2 | CB4: =_xlfn.QUARTILE.INC(F$12:F$36,$CA4) -> -1.2769 | CC4: =_xlfn.QUARTILE.INC(G$12:G$36,$CA4) -> 0.3021 | CD4: =_xlfn.QUARTILE.INC(H$12:H$36,$CA4) -> 3.9734 | CE4: =_xlfn.QUARTILE.INC(I$12:I$36,$CA4) -> 7.3478 | CF4: =_xlfn.QUARTILE.INC(J$12:J$36,$CA4) -> 6.2301 | CG4: =_xlfn.QUARTILE.INC(K$12:K$36,$CA4) -> 5.69075 | CH4: =_xlfn.QUARTILE.INC(L$12:L$36,$CA4) -> 5.5532 | CI4: =_xlfn.QUARTILE.INC(M$12:M$36,$CA4) -> 6.23005 | ... CQ4: =_xlfn.QUARTILE.INC(U$12:U$36,$CA4) -> 6.7414
CA5: 3 | CB5: =_xlfn.QUARTILE.INC(F$12:F$36,$CA5) -> -0.959 | CC5: =_xlfn.QUARTILE.INC(G$12:G$36,$CA5) -> 0.5658 | CD5: =_xlfn.QUARTILE.INC(H$12:H$36,$CA5) -> 4.1166 | CE5: =_xlfn.QUARTILE.INC(I$12:I$36,$CA5) -> 7.5029 | CF5: =_xlfn.QUARTILE.INC(J$12:J$36,$CA5) -> 6.3234 | CG5: =_xlfn.QUARTILE.INC(K$12:K$36,$CA5) -> 5.7699 | CH5: =_xlfn.QUARTILE.INC(L$12:L$36,$CA5) -> 5.682 | CI5: =_xlfn.QUARTILE.INC(M$12:M$36,$CA5) -> 6.297725 | ... CQ5: =_xlfn.QUARTILE.INC(U$12:U$36,$CA5) -> 7.0435
CB6: =_xlfn.QUARTILE.INC(F$12:F$36,$CA6) -> -1.9426 | CC6: =_xlfn.QUARTILE.INC(G$12:G$36,$CA6) -> -0.3119 | CD6: =_xlfn.QUARTILE.INC(H$12:H$36,$CA6) -> 2.7972 | CE6: =_xlfn.QUARTILE.INC(I$12:I$36,$CA6) -> 3.9817 | CF6: =_xlfn.QUARTILE.INC(J$12:J$36,$CA6) -> 4.7597 | CG6: =_xlfn.QUARTILE.INC(K$12:K$36,$CA6) -> 5.257 | CH6: =_xlfn.QUARTILE.INC(L$12:L$36,$CA6) -> 4.3557 | CI6: =_xlfn.QUARTILE.INC(M$12:M$36,$CA6) -> 5.7593 | ... CQ6: =_xlfn.QUARTILE.INC(U$12:U$36,$CA6) -> 4.7199
A7: Fund Barometer - Money Market Fund | CA7: 4 | CB7: =_xlfn.QUARTILE.INC(F$12:F$36,$CA7) -> 0.8689 | CC7: =_xlfn.QUARTILE.INC(G$12:G$36,$CA7) -> 1.9289 | CD7: =_xlfn.QUARTILE.INC(H$12:H$36,$CA7) -> 4.8624 | CE7: =_xlfn.QUARTILE.INC(I$12:I$36,$CA7) -> 7.8209 | CF7: =_xlfn.QUARTILE.INC(J$12:J$36,$CA7) -> 6.4843 | CG7: =_xlfn.QUARTILE.INC(K$12:K$36,$CA7) -> 5.844 | CH7: =_xlfn.QUARTILE.INC(L$12:L$36,$CA7) -> 5.8461 | CI7: =_xlfn.QUARTILE.INC(M$12:M$36,$CA7) -> 6.3445 | ... CQ7: =_xlfn.QUARTILE.INC(U$12:U$36,$CA7) -> 7.31
A8: ='Liquid Fund'!A8 -> (As on 30 Apr 2026) | B8: Value Information | F8: Simple Annualized (%) | M8: Compound Annualized (%) | U8: Since Inception | V8: Quartile | AL8: Credit Quality | AO8: Modified Duration (Years) | AP8: Average Maturity (Years) | AQ8: YTM | AR8: Expense Ratio(%)
A9: Scheme Name | B9: Launch Date | C9: Fund Size (Rs Crs) Feb26 | D9: Fund Size (Rs Crs) Mar26 | E9: Latest NAV | F9: 7 Days | G9: 14 Days | H9: 21 Days | I9: 1 Month | J9: 3 Months | K9: 6 Months | L9: YTD | M9: 1 Year | N9: 2 Years | O9: 3 Years | P9: 4 Years | Q9: 5 Years | R9: 7 Years | S9: 10 Years | T9: 15 Years | V9: 7 Days | W9: 14 Days | X9: 21 Days | Y9: 1 Month | Z9: 3 Months | AA9: 6 Months | AB9: YTD | AC9: 1 Year | AD9: 2 Years | AE9: 3 Years | AF9: 4 Years | AG9: 5 Years | AH9: 7 Years | AI9: 10 Years | AJ9: 15 Years | AK9: Since Inception | AL9: AA minus and Above | AM9: Below AA minus | AN9: Cash & Cash Equivalent
A10: To view Exit Loads of any Scheme in this group please click here
A11: Money Market Fund
A12: Aditya Birla SL Money Manager Fund(G) | B12: 38638 | C12: 30777.544 | D12: 28780.111 | E12: 389.1462 | F12: -1.4092 | G12: 0.0837 | H12: 3.9649 | I12: 7.5802 | J12: 6.4843 | K12: 5.6983 | L12: 5.5757 | M12: 6.2975 | N12: 7.1418 | O12: 7.2752 | P12: 6.9668 | Q12: 6.3495 | R12: 6.4322 | S12: 6.7277 | T12: 7.5249 | U12: 6.8318 | V12: =IF(F12="",0,IF(F12<=CB$3,4,IF(F12>=CB$5,1,IF(F12>=CB$4,2,3)))) -> 3 | W12: =IF(G12="",0,IF(G12<=CC$3,4,IF(G12>=CC$5,1,IF(G12>=CC$4,2,3)))) -> 3 | X12: =IF(H12="",0,IF(H12<=CD$3,4,IF(H12>=CD$5,1,IF(H12>=CD$4,2,3)))) -> 3 | Y12: =IF(I12="",0,IF(I12<=CE$3,4,IF(I12>=CE$5,1,IF(I12>=CE$4,2,3)))) -> 1 | Z12: =IF(J12="",0,IF(J12<=CF$3,4,IF(J12>=CF$5,1,IF(J12>=CF$4,2,3)))) -> 1 | AA12: =IF(K12="",0,IF(K12<=CG$3,4,IF(K12>=CG$5,1,IF(K12>=CG$4,2,3)))) -> 2 | AB12: =IF(L12="",0,IF(L12<=CH$3,4,IF(L12>=CH$5,1,IF(L12>=CH$4,2,3)))) -> 2 | AC12: =IF(M12="",0,IF(M12<=CI$3,4,IF(M12>=CI$5,1,IF(M12>=CI$4,2,3)))) -> 2 | ... AK12: =IF(U12="",0,IF(U12<=CQ$3,4,IF(U12>=CQ$5,1,IF(U12>=CQ$4,2,3)))) -> 2 | AL12: 101.6149 | AM12: 0.2759 | AN12: -1.8908 | AO12: 0.76 | AP12: 0.76 | AQ12: 7.38 | AR12: 0.37
